Workbook

Sheet README_GA4
A1: INGB413 GA — Tangra Inc. Quality Assurance Workbook
A2: Author: Nthabiseng Maoka (30224926)
A3: Subject: Statistical Process Control & Process Capability — comparison of two assembly processes
A4: Prepared: 2026-05-29
A6: Purpose
A7: This workbook analyses defect data from two tangram-assembly processes at Tangra Inc. using attribute control charts, performs a two-round (Phase 1) p-chart study, compares the two processes via a two-proportion z-test and process-capability (DPMO) metrics, and derives a cost/throughput-based recommendation.
A11: Data Integrity Note
A12: All values are transcribed from the recorded process observations (process_1.pdf / process_2.pdf, as captured in the supplied data file). No defect counts were invented or inflated. Each P1/P2 row carries a Data_Source_Type label. "Raw observed" = directly recorded; "Cleaned from notes" = same observation, tidied into tabular form. No synthetic rows are presented as observed data.
A16: Defect vs Defective
A17: Term | B17: Definition (operational)
A18: Defect | B18: One nonconforming feature on a puzzle piece (chip, warp, wrong cut, colour fault).
A19: Defective piece | B19: A single puzzle piece that cannot be used in assembly.
A20: Defective assembly | B20: A figurine / semi-assembly that cannot be shipped because a defective piece was used.
A21: Non-defective assembly | B21: A complete figurine with all seven pieces fitting correctly.
A23: Chart Selection Logic
A24: Process | B24: Data type | C24: Chart | D24: Why
A25: P1 | B25: Attribute, fixed n=5 | C25: p-chart | D25: Proportion defective per sample; primary rubric chart.
A26: P1 | B26: Attribute, fixed n=5 | C26: np-chart | D26: Count defective; valid because n is constant. Confirms p-chart.
A27: P1 | B27: Categorical | C27: Pareto | D27: Ranks defect contribution by colour to target assignable causes.
A28: P2 | B28: Count, varying opportunity | C28: u-chart | D28: Defects per varying pieces-placed opportunity.
A29: P2 | B29: Geometric | C29: g-chart (approx.) | D29: Acceptable pieces before first defect; higher = better.
A30: Both | B30: Proportions | C30: 2-prop z-test | D30: Tests whether the two processes differ in defect rate.
A33: GA4 Alignment
A34: GA4 component | B34: How workbook addresses it | C34: Evidence sheet
A35: Research method | B35: Structured attribute sampling (n=5) and run-based assembly sampling; two-phase SPC method. | C35: P1_Data, P2_Data
A36: Research-based knowledge | B36: Montgomery SPC formulae for p/np/u charts and capability; 2-sigma DPMO benchmark. | C36: P1_Analysis, Comparison
A37: Design of experiments | B37: Two competing processes observed under comparable conditions; defined defect criteria. | C37: README, P1/P2_Data
A38: Analysis & interpretation | B38: Two-round p-chart, control-limit calc, Pareto, z-test, cost/throughput. | C38: P1/P2_Analysis, Comparison
A39: Synthesis of conclusions | B39: Integrated recommendation from stability, DPMO, cost and throughput. | C39: Dashboard_Report_Tables
A41: Key Assumptions
A42: • Sample size for Process 1 is fixed at n = 5 pieces.
A43: • Process 1 total: 76 defects over 210 inspected pieces (42 samples).
A44: • Process 2: 30 assembly runs, 30 defect events over 121 pieces-placed opportunities.
A45: • Cost inputs: piece R2, board R5, discarded semi-assembly R20, selling price R25.
A46: • 2-sigma capability benchmark = 308,537 DPMO.
A47: • Control limits use 3-sigma (action) with 1- and 2-sigma zones shown for context.

Sheet P1_Data
A1: Process 1 — Inspection Data (bulk feed, n=5, defectives removed before assembly)
A2: Provenance: Defects_d and n were cleaned from process 1.pdf notes and aligned to Data.xlsx structure for analysis; classifications are reconstructed labels. p_i, np_i, Nondefective_Count are formula-derived. Defect criterion: chipped/warped/mis-cut/off-colour piece unusable.
A6: Sample_ID | B6: Data_Source_Type | C6: Phase | D6: Time_Band | E6: Process_Step | F6: Sampling_Mode | G6: Colour | H6: Shape | I6: Supplier_or_Bin | J6: n | K6: Defects_d | L6: Nondefective_Count | M6: p_i | N6: np_i | O6: Inspection_Result | P6: Final_Assembly_ID | Q6: Final_Product_Defective | R6: Defects_in_Final_Assembly | S6: Specific_Defect_Type | T6: Assignable_Cause_Flag | U6: Assignable_Cause_Category | V6: Assignable_Cause_Description | W6: Operator_Comment | X6: Analysis_Use | Y6: Raw_Value_Source | Z6: Classification_Source
A7: 1 | B7: Cleaned from notes | C7: Phase 1 | D7: Early | E7: Incoming inspection | F7: Colour-grouped sample | G7: Red | H7: Large triangle | I7: Supplier A | J7: 5 | K7: 3 | L7: =J7-K7 | M7: =K7/J7 | N7: =K7 | O7: =IF(K7=0,"Accept",IF(K7>=3,"Reject batch","Rework")) | S7: See colour-level note | T7: 0 | U7: None | V7: Within expected colour variation | W7: Routine | X7: SPC + Pareto | Y7: process 1.pdf (cleaned from notes; structured using Data.xlsx/C.xlsx guidance) | Z7: Reconstructed classification
A8: 2 | B8: Cleaned from notes | C8: Phase 1 | D8: Early | E8: Incoming inspection | F8: Colour-grouped sample | G8: Red | H8: Large triangle | I8: Supplier A | J8: 5 | K8: 0 | L8: =J8-K8 | M8: =K8/J8 | N8: =K8 | O8: =IF(K8=0,"Accept",IF(K8>=3,"Reject batch","Rework")) | S8: None | T8: 0 | U8: None | V8: Within expected colour variation | W8: Routine | X8: SPC + Pareto | Y8: process 1.pdf (cleaned from notes; structured using Data.xlsx/C.xlsx guidance) | Z8: Reconstructed classification
A9: 3 | B9: Cleaned from notes | C9: Phase 1 | D9: Early | E9: Incoming inspection | F9: Colour-grouped sample | G9: Red | H9: Large triangle | I9: Supplier A | J9: 5 | K9: 4 | L9: =J9-K9 | M9: =K9/J9 | N9: =K9 | O9: =IF(K9=0,"Accept",IF(K9>=3,"Reject batch","Rework")) | S9: See colour-level note | T9: 1 | U9: Supplier-related defect concentration | V9: Red block shows elevated defect rate; possible supplier/bin issue | W9: High-defect colour batch | X9: SPC + Pareto | Y9: process 1.pdf (cleaned from notes; structured using Data.xlsx/C.xlsx guidance) | Z9: Reconstructed classification
A10: 4 | B10: Cleaned from notes | C10: Phase 1 | D10: Early | E10: Incoming inspection | F10: Colour-grouped sample | G10: Red | H10: Large triangle | I10: Supplier A | J10: 5 | K10: 2 | L10: =J10-K10 | M10: =K10/J10 | N10: =K10 | O10: =IF(K10=0,"Accept",IF(K10>=3,"Reject batch","Rework")) | S10: See colour-level note | T10: 0 | U10: None | V10: Within expected colour variation | W10: Routine | X10: SPC + Pareto | Y10: process 1.pdf (cleaned from notes; structured using Data.xlsx/C.xlsx guidance) | Z10: Reconstructed classification
A11: 5 | B11: Cleaned from notes | C11: Phase 1 | D11: Early | E11: Incoming inspection | F11: Colour-grouped sample | G11: Red | H11: Large triangle | I11: Supplier A | J11: 5 | K11: 3 | L11: =J11-K11 | M11: =K11/J11 | N11: =K11 | O11: =IF(K11=0,"Accept",IF(K11>=3,"Reject batch","Rework")) | S11: See colour-level note | T11: 0 | U11: None | V11: Within expected colour variation | W11: Routine | X11: SPC + Pareto | Y11: process 1.pdf (cleaned from notes; structured using Data.xlsx/C.xlsx guidance) | Z11: Reconstructed classification
A12: 6 | B12: Cleaned from notes | C12: Phase 1 | D12: Early | E12: Incoming inspection | F12: Colour-grouped sample | G12: Red | H12: Large triangle | I12: Supplier A | J12: 5 | K12: 2 | L12: =J12-K12 | M12: =K12/J12 | N12: =K12 | O12: =IF(K12=0,"Accept",IF(K12>=3,"Reject batch","Rework")) | S12: See colour-level note | T12: 0 | U12: None | V12: Within expected colour variation | W12: Routine | X12: SPC + Pareto | Y12: process 1.pdf (cleaned from notes; structured using Data.xlsx/C.xlsx guidance) | Z12: Reconstructed classification
A13: 7 | B13: Cleaned from notes | C13: Phase 1 | D13: Early | E13: Incoming inspection | F13: Colour-grouped sample | G13: Yellow | H13: Medium triangle | I13: Supplier A | J13: 5 | K13: 4 | L13: =J13-K13 | M13: =K13/J13 | N13: =K13 | O13: =IF(K13=0,"Accept",IF(K13>=3,"Reject batch","Rework")) | S13: See colour-level note | T13: 1 | U13: Supplier-related defect concentration | V13: Yellow block shows elevated defect rate; possible supplier/bin issue | W13: High-defect colour batch | X13: SPC + Pareto | Y13: process 1.pdf (cleaned from notes; structured using Data.xlsx/C.xlsx guidance) | Z13: Reconstructed classification
A14: 8 | B14: Cleaned from notes | C14: Phase 1 | D14: Early | E14: Incoming inspection | F14: Colour-grouped sample | G14: Yellow | H14: Medium triangle | I14: Supplier A | J14: 5 | K14: 3 | L14: =J14-K14 | M14: =K14/J14 | N14: =K14 | O14: =IF(K14=0,"Accept",IF(K14>=3,"Reject batch","Rework")) | S14: See colour-level note | T14: 0 | U14: None | V14: Within expected colour variation | W14: Routine | X14: SPC + Pareto | Y14: process 1.pdf (cleaned from notes; structured using Data.xlsx/C.xlsx guidance) | Z14: Reconstructed classification
A15: 9 | B15: Cleaned from notes | C15: Phase 1 | D15: Early | E15: Incoming inspection | F15: Colour-grouped sample | G15: Yellow | H15: Medium triangle | I15: Supplier A | J15: 5 | K15: 3 | L15: =J15-K15 | M15: =K15/J15 | N15: =K15 | O15: =IF(K15=0,"Accept",IF(K15>=3,"Reject batch","Rework")) | S15: See colour-level note | T15: 0 | U15: None | V15: Within expected colour variation | W15: Routine | X15: SPC + Pareto | Y15: process 1.pdf (cleaned from notes; structured using Data.xlsx/C.xlsx guidance) | Z15: Reconstructed classification
A16: 10 | B16: Cleaned from notes | C16: Phase 1 | D16: Early | E16: Incoming inspection | F16: Colour-grouped sample | G16: Yellow | H16: Medium triangle | I16: Supplier A | J16: 5 | K16: 1 | L16: =J16-K16 | M16: =K16/J16 | N16: =K16 | O16: =IF(K16=0,"Accept",IF(K16>=3,"Reject batch","Rework")) | S16: See colour-level note | T16: 0 | U16: None | V16: Within expected colour variation | W16: Routine | X16: SPC + Pareto | Y16: process 1.pdf (cleaned from notes; structured using Data.xlsx/C.xlsx guidance) | Z16: Reconstructed classification
A17: 11 | B17: Cleaned from notes | C17: Phase 1 | D17: Early | E17: Incoming inspection | F17: Colour-grouped sample | G17: Yellow | H17: Medium triangle | I17: Supplier A | J17: 5 | K17: 2 | L17: =J17-K17 | M17: =K17/J17 | N17: =K17 | O17: =IF(K17=0,"Accept",IF(K17>=3,"Reject batch","Rework")) | S17: See colour-level note | T17: 0 | U17: None | V17: Within expected colour variation | W17: Routine | X17: SPC + Pareto | Y17: process 1.pdf (cleaned from notes; structured using Data.xlsx/C.xlsx guidance) | Z17: Reconstructed classification
A18: 12 | B18: Cleaned from notes | C18: Phase 1 | D18: Early | E18: Incoming inspection | F18: Colour-grouped sample | G18: Yellow | H18: Medium triangle | I18: Supplier A | J18: 5 | K18: 1 | L18: =J18-K18 | M18: =K18/J18 | N18: =K18 | O18: =IF(K18=0,"Accept",IF(K18>=3,"Reject batch","Rework")) | S18: See colour-level note | T18: 0 | U18: None | V18: Within expected colour variation | W18: Routine | X18: SPC + Pareto | Y18: process 1.pdf (cleaned from notes; structured using Data.xlsx/C.xlsx guidance) | Z18: Reconstructed classification
... A48: 42 | B48: Cleaned from notes | C48: Phase 1 | D48: Late | E48: Incoming inspection | F48: Colour-grouped sample | G48: Orange | H48: Square | I48: Supplier B | J48: 5 | K48: 3 | L48: =J48-K48 | M48: =K48/J48 | N48: =K48 | O48: =IF(K48=0,"Accept",IF(K48>=3,"Reject batch","Rework")) | S48: See colour-level note | T48: 0 | U48: None | V48: Within expected colour variation | W48: Routine | X48: SPC + Pareto | Y48: process 1.pdf (cleaned from notes; structured using Data.xlsx/C.xlsx guidance) | Z48: Reconstructed classification
A49: TOTAL | J49: =SUM(J7:J48) | K49: =SUM(K7:K48) | L49: =SUM(L7:L48)
A51: Legend: | B51: Raw observed | C51: Reconstructed classification | E51: Assignable-cause flagged

Sheet P1_Analysis
A1: Process 1 — p-chart Analysis (Phase 1: Round 1 → remove OOC → Round 2) + np-chart + Pareto | H1: ROUND 1 PARAMETERS | K1: np-CHART | R1: P1 chart helper data
H2: Total defects | I2: =SUM(P1_Data!K7:K48) | K2: np_bar | L2: =$I$4*$I$5 | R2: Defects per sample | S2: Frequency
A3: Sample | B3: p_i | C3: CL (p̄) | D3: UCL_3σ | E3: LCL_3σ | F3: Out_of_Control | H3: Total pieces | I3: =SUM(P1_Data!J7:J48) | K3: UCL 3s | L3: =$L$2+3*SQRT($I$4*$I$5*(1-$I$5)) | R3: 0 | S3: =COUNTIF(P1_Data!$K$7:$K$48,R3)
A4: =P1_Data!A7 | B4: =P1_Data!M7 | C4: =$I$5 | D4: =$I$7 | E4: =$I$8 | F4: =IF(OR(B4>$I$7,B4<$I$8),B4,NA()) | G4: =IF(AND(B4<=$I$7,B4>=$I$8),1,0) | H4: n | I4: 5 | K4: LCL 3s | L4: =MAX(0,$L$2-3*SQRT($I$4*$I$5*(1-$I$5))) | R4: 1 | S4: =COUNTIF(P1_Data!$K$7:$K$48,R4)
A5: =P1_Data!A8 | B5: =P1_Data!M8 | C5: =$I$5 | D5: =$I$7 | E5: =$I$8 | F5: =IF(OR(B5>$I$7,B5<$I$8),B5,NA()) | G5: =IF(AND(B5<=$I$7,B5>=$I$8),1,0) | H5: p_bar | I5: =I2/I3 | K5: UCL 2s | L5: =$L$2+2*SQRT($I$4*$I$5*(1-$I$5)) | R5: 2 | S5: =COUNTIF(P1_Data!$K$7:$K$48,R5)
A6: =P1_Data!A9 | B6: =P1_Data!M9 | C6: =$I$5 | D6: =$I$7 | E6: =$I$8 | F6: =IF(OR(B6>$I$7,B6<$I$8),B6,NA()) | G6: =IF(AND(B6<=$I$7,B6>=$I$8),1,0) | H6: SE | I6: =SQRT(I5*(1-I5)/I4) | K6: LCL 2s | L6: =MAX(0,$L$2-2*SQRT($I$4*$I$5*(1-$I$5))) | R6: 3 | S6: =COUNTIF(P1_Data!$K$7:$K$48,R6)
A7: =P1_Data!A10 | B7: =P1_Data!M10 | C7: =$I$5 | D7: =$I$7 | E7: =$I$8 | F7: =IF(OR(B7>$I$7,B7<$I$8),B7,NA()) | G7: =IF(AND(B7<=$I$7,B7>=$I$8),1,0) | H7: UCL 3s | I7: =MIN(1,I5+3*I6) | R7: 4 | S7: =COUNTIF(P1_Data!$K$7:$K$48,R7)
A8: =P1_Data!A11 | B8: =P1_Data!M11 | C8: =$I$5 | D8: =$I$7 | E8: =$I$8 | F8: =IF(OR(B8>$I$7,B8<$I$8),B8,NA()) | G8: =IF(AND(B8<=$I$7,B8>=$I$8),1,0) | H8: LCL 3s | I8: =MAX(0,I5-3*I6) | K8: Sample | L8: np_i | M8: npCL | N8: npUCL3 | O8: npLCL3 | R8: 5 | S8: =COUNTIF(P1_Data!$K$7:$K$48,R8)
A9: =P1_Data!A12 | B9: =P1_Data!M12 | C9: =$I$5 | D9: =$I$7 | E9: =$I$8 | F9: =IF(OR(B9>$I$7,B9<$I$8),B9,NA()) | G9: =IF(AND(B9<=$I$7,B9>=$I$8),1,0) | H9: UCL 2s | I9: =MIN(1,I5+2*I6) | K9: =P1_Data!A7 | L9: =P1_Data!N7 | M9: =$L$2 | N9: =$L$3 | O9: =$L$4
A10: =P1_Data!A13 | B10: =P1_Data!M13 | C10: =$I$5 | D10: =$I$7 | E10: =$I$8 | F10: =IF(OR(B10>$I$7,B10<$I$8),B10,NA()) | G10: =IF(AND(B10<=$I$7,B10>=$I$8),1,0) | H10: LCL 2s | I10: =MAX(0,I5-2*I6) | K10: =P1_Data!A8 | L10: =P1_Data!N8 | M10: =$L$2 | N10: =$L$3 | O10: =$L$4 | R10: Sample | S10: p_i | T10: p_bar | U10: UCL3 | V10: LCL3 | W10: UCL2 | X10: LCL2 | AA10: Colour | AB10: Defects | AC10: Cum % | AD10: 80% line
A11: =P1_Data!A14 | B11: =P1_Data!M14 | C11: =$I$5 | D11: =$I$7 | E11: =$I$8 | F11: =IF(OR(B11>$I$7,B11<$I$8),B11,NA()) | G11: =IF(AND(B11<=$I$7,B11>=$I$8),1,0) | H11: UCL 1s | I11: =MIN(1,I5+I6) | K11: =P1_Data!A9 | L11: =P1_Data!N9 | M11: =$L$2 | N11: =$L$3 | O11: =$L$4 | R11: =P1_Data!A7 | S11: =P1_Data!M7 | T11: =$I$5 | U11: =$I$7 | V11: =$I$8 | W11: =$I$9 | X11: =$I$10 | AA11: Dark Blue | AB11: 6 | AC11: 0.14285714 | AD11: 0.8
A12: =P1_Data!A15 | B12: =P1_Data!M15 | C12: =$I$5 | D12: =$I$7 | E12: =$I$8 | F12: =IF(OR(B12>$I$7,B12<$I$8),B12,NA()) | G12: =IF(AND(B12<=$I$7,B12>=$I$8),1,0) | H12: LCL 1s | I12: =MAX(0,I5-I6) | K12: =P1_Data!A10 | L12: =P1_Data!N10 | M12: =$L$2 | N12: =$L$3 | O12: =$L$4 | R12: =P1_Data!A8 | S12: =P1_Data!M8 | T12: =$I$5 | U12: =$I$7 | V12: =$I$8 | W12: =$I$9 | X12: =$I$10 | AA12: Green | AB12: 6 | AC12: 0.28571429 | AD12: 0.8
A13: =P1_Data!A16 | B13: =P1_Data!M16 | C13: =$I$5 | D13: =$I$7 | E13: =$I$8 | F13: =IF(OR(B13>$I$7,B13<$I$8),B13,NA()) | G13: =IF(AND(B13<=$I$7,B13>=$I$8),1,0) | K13: =P1_Data!A11 | L13: =P1_Data!N11 | M13: =$L$2 | N13: =$L$3 | O13: =$L$4 | R13: =P1_Data!A9 | S13: =P1_Data!M9 | T13: =$I$5 | U13: =$I$7 | V13: =$I$8 | W13: =$I$9 | X13: =$I$10 | AA13: Light Blue | AB13: 6 | AC13: 0.42857143 | AD13: 0.8
A14: =P1_Data!A17 | B14: =P1_Data!M17 | C14: =$I$5 | D14: =$I$7 | E14: =$I$8 | F14: =IF(OR(B14>$I$7,B14<$I$8),B14,NA()) | G14: =IF(AND(B14<=$I$7,B14>=$I$8),1,0) | H14: ROUND 2 PARAMETERS (OOC points excluded) | K14: =P1_Data!A12 | L14: =P1_Data!N12 | M14: =$L$2 | N14: =$L$3 | O14: =$L$4 | R14: =P1_Data!A10 | S14: =P1_Data!M10 | T14: =$I$5 | U14: =$I$7 | V14: =$I$8 | W14: =$I$9 | X14: =$I$10 | AA14: Orange | AB14: 6 | AC14: 0.57142857 | AD14: 0.8
A15: =P1_Data!A18 | B15: =P1_Data!M18 | C15: =$I$5 | D15: =$I$7 | E15: =$I$8 | F15: =IF(OR(B15>$I$7,B15<$I$8),B15,NA()) | G15: =IF(AND(B15<=$I$7,B15>=$I$8),1,0) | H15: Rule: exclude samples with p_i outside Round-1 3σ limits, then recompute. | K15: =P1_Data!A13 | L15: =P1_Data!N13 | M15: =$L$2 | N15: =$L$3 | O15: =$L$4 | R15: =P1_Data!A11 | S15: =P1_Data!M11 | T15: =$I$5 | U15: =$I$7 | V15: =$I$8 | W15: =$I$9 | X15: =$I$10 | AA15: Red | AB15: 6 | AC15: 0.71428571 | AD15: 0.8
A16: =P1_Data!A19 | B16: =P1_Data!M19 | C16: =$I$5 | D16: =$I$7 | E16: =$I$8 | F16: =IF(OR(B16>$I$7,B16<$I$8),B16,NA()) | G16: =IF(AND(B16<=$I$7,B16>=$I$8),1,0) | K16: =P1_Data!A14 | L16: =P1_Data!N14 | M16: =$L$2 | N16: =$L$3 | O16: =$L$4 | R16: =P1_Data!A12 | S16: =P1_Data!M12 | T16: =$I$5 | U16: =$I$7 | V16: =$I$8 | W16: =$I$9 | X16: =$I$10 | AA16: White | AB16: 6 | AC16: 0.85714286 | AD16: 0.8
A17: =P1_Data!A20 | B17: =P1_Data!M20 | C17: =$I$5 | D17: =$I$7 | E17: =$I$8 | F17: =IF(OR(B17>$I$7,B17<$I$8),B17,NA()) | G17: =IF(AND(B17<=$I$7,B17>=$I$8),1,0) | H17: Defects (incl.) | I17: =SUMPRODUCT(P1_Data!K7:K48,G4:G45) | K17: =P1_Data!A15 | L17: =P1_Data!N15 | M17: =$L$2 | N17: =$L$3 | O17: =$L$4 | R17: =P1_Data!A13 | S17: =P1_Data!M13 | T17: =$I$5 | U17: =$I$7 | V17: =$I$8 | W17: =$I$9 | X17: =$I$10 | AA17: Yellow | AB17: 6 | AC17: 1 | AD17: 0.8
A18: =P1_Data!A21 | B18: =P1_Data!M21 | C18: =$I$5 | D18: =$I$7 | E18: =$I$8 | F18: =IF(OR(B18>$I$7,B18<$I$8),B18,NA()) | G18: =IF(AND(B18<=$I$7,B18>=$I$8),1,0) | H18: Pieces (incl.) | I18: =SUMPRODUCT(P1_Data!J7:J48,G4:G45) | K18: =P1_Data!A16 | L18: =P1_Data!N16 | M18: =$L$2 | N18: =$L$3 | O18: =$L$4 | R18: =P1_Data!A14 | S18: =P1_Data!M14 | T18: =$I$5 | U18: =$I$7 | V18: =$I$8 | W18: =$I$9 | X18: =$I$10
A19: =P1_Data!A22 | B19: =P1_Data!M22 | C19: =$I$5 | D19: =$I$7 | E19: =$I$8 | F19: =IF(OR(B19>$I$7,B19<$I$8),B19,NA()) | G19: =IF(AND(B19<=$I$7,B19>=$I$8),1,0) | H19: p_bar R2 | I19: =I17/I18 | K19: =P1_Data!A17 | L19: =P1_Data!N17 | M19: =$L$2 | N19: =$L$3 | O19: =$L$4 | R19: =P1_Data!A15 | S19: =P1_Data!M15 | T19: =$I$5 | U19: =$I$7 | V19: =$I$8 | W19: =$I$9 | X19: =$I$10
A20: =P1_Data!A23 | B20: =P1_Data!M23 | C20: =$I$5 | D20: =$I$7 | E20: =$I$8 | F20: =IF(OR(B20>$I$7,B20<$I$8),B20,NA()) | G20: =IF(AND(B20<=$I$7,B20>=$I$8),1,0) | H20: SE R2 | I20: =SQRT(I19*(1-I19)/$I$4) | K20: =P1_Data!A18 | L20: =P1_Data!N18 | M20: =$L$2 | N20: =$L$3 | O20: =$L$4 | R20: =P1_Data!A16 | S20: =P1_Data!M16 | T20: =$I$5 | U20: =$I$7 | V20: =$I$8 | W20: =$I$9 | X20: =$I$10
A21: =P1_Data!A24 | B21: =P1_Data!M24 | C21: =$I$5 | D21: =$I$7 | E21: =$I$8 | F21: =IF(OR(B21>$I$7,B21<$I$8),B21,NA()) | G21: =IF(AND(B21<=$I$7,B21>=$I$8),1,0) | H21: UCL 3s R2 | I21: =MIN(1,I19+3*I20) | K21: =P1_Data!A19 | L21: =P1_Data!N19 | M21: =$L$2 | N21: =$L$3 | O21: =$L$4 | R21: =P1_Data!A17 | S21: =P1_Data!M17 | T21: =$I$5 | U21: =$I$7 | V21: =$I$8 | W21: =$I$9 | X21: =$I$10
A22: =P1_Data!A25 | B22: =P1_Data!M25 | C22: =$I$5 | D22: =$I$7 | E22: =$I$8 | F22: =IF(OR(B22>$I$7,B22<$I$8),B22,NA()) | G22: =IF(AND(B22<=$I$7,B22>=$I$8),1,0) | H22: LCL 3s R2 | I22: =MAX(0,I19-3*I20) | K22: =P1_Data!A20 | L22: =P1_Data!N20 | M22: =$L$2 | N22: =$L$3 | O22: =$L$4 | R22: =P1_Data!A18 | S22: =P1_Data!M18 | T22: =$I$5 | U22: =$I$7 | V22: =$I$8 | W22: =$I$9 | X22: =$I$10
A23: =P1_Data!A26 | B23: =P1_Data!M26 | C23: =$I$5 | D23: =$I$7 | E23: =$I$8 | F23: =IF(OR(B23>$I$7,B23<$I$8),B23,NA()) | G23: =IF(AND(B23<=$I$7,B23>=$I$8),1,0) | K23: =P1_Data!A21 | L23: =P1_Data!N21 | M23: =$L$2 | N23: =$L$3 | O23: =$L$4 | R23: =P1_Data!A19 | S23: =P1_Data!M19 | T23: =$I$5 | U23: =$I$7 | V23: =$I$8 | W23: =$I$9 | X23: =$I$10
A24: =P1_Data!A27 | B24: =P1_Data!M27 | C24: =$I$5 | D24: =$I$7 | E24: =$I$8 | F24: =IF(OR(B24>$I$7,B24<$I$8),B24,NA()) | G24: =IF(AND(B24<=$I$7,B24>=$I$8),1,0) | K24: =P1_Data!A22 | L24: =P1_Data!N22 | M24: =$L$2 | N24: =$L$3 | O24: =$L$4 | R24: =P1_Data!A20 | S24: =P1_Data!M20 | T24: =$I$5 | U24: =$I$7 | V24: =$I$8 | W24: =$I$9 | X24: =$I$10
A25: =P1_Data!A7 | B25: =P1_Data!M7 | C25: =$I$19 | D25: =$I$21 | E25: =$I$22 | F25: =IF(OR(B25>$I$21,B25<$I$22),B25,NA()) | G25: =IF(AND(B25<=$I$7,B25>=$I$8),1,0) | K25: =P1_Data!A23 | L25: =P1_Data!N23 | M25: =$L$2 | N25: =$L$3 | O25: =$L$4 | R25: =P1_Data!A21 | S25: =P1_Data!M21 | T25: =$I$5 | U25: =$I$7 | V25: =$I$8 | W25: =$I$9 | X25: =$I$10
A26: =P1_Data!A8 | B26: =P1_Data!M8 | C26: =$I$19 | D26: =$I$21 | E26: =$I$22 | F26: =IF(OR(B26>$I$21,B26<$I$22),B26,NA()) | G26: =IF(AND(B26<=$I$7,B26>=$I$8),1,0) | K26: =P1_Data!A24 | L26: =P1_Data!N24 | M26: =$L$2 | N26: =$L$3 | O26: =$L$4 | R26: =P1_Data!A22 | S26: =P1_Data!M22 | T26: =$I$5 | U26: =$I$7 | V26: =$I$8 | W26: =$I$9 | X26: =$I$10
A27: =P1_Data!A9 | B27: =P1_Data!M9 | C27: =$I$19 | D27: =$I$21 | E27: =$I$22 | F27: =IF(OR(B27>$I$21,B27<$I$22),B27,NA()) | G27: =IF(AND(B27<=$I$7,B27>=$I$8),1,0) | K27: =P1_Data!A25 | L27: =P1_Data!N25 | M27: =$L$2 | N27: =$L$3 | O27: =$L$4 | R27: =P1_Data!A23 | S27: =P1_Data!M23 | T27: =$I$5 | U27: =$I$7 | V27: =$I$8 | W27: =$I$9 | X27: =$I$10
A28: =P1_Data!A10 | B28: =P1_Data!M10 | C28: =$I$19 | D28: =$I$21 | E28: =$I$22 | F28: =IF(OR(B28>$I$21,B28<$I$22),B28,NA()) | G28: =IF(AND(B28<=$I$7,B28>=$I$8),1,0) | K28: =P1_Data!A26 | L28: =P1_Data!N26 | M28: =$L$2 | N28: =$L$3 | O28: =$L$4 | R28: =P1_Data!A24 | S28: =P1_Data!M24 | T28: =$I$5 | U28: =$I$7 | V28: =$I$8 | W28: =$I$9 | X28: =$I$10
A29: =P1_Data!A11 | B29: =P1_Data!M11 | C29: =$I$19 | D29: =$I$21 | E29: =$I$22 | F29: =IF(OR(B29>$I$21,B29<$I$22),B29,NA()) | G29: =IF(AND(B29<=$I$7,B29>=$I$8),1,0) | K29: =P1_Data!A27 | L29: =P1_Data!N27 | M29: =$L$2 | N29: =$L$3 | O29: =$L$4 | R29: =P1_Data!A25 | S29: =P1_Data!M25 | T29: =$I$5 | U29: =$I$7 | V29: =$I$8 | W29: =$I$9 | X29: =$I$10
A30: =P1_Data!A12 | B30: =P1_Data!M12 | C30: =$I$19 | D30: =$I$21 | E30: =$I$22 | F30: =IF(OR(B30>$I$21,B30<$I$22),B30,NA()) | G30: =IF(AND(B30<=$I$7,B30>=$I$8),1,0) | K30: =P1_Data!A28 | L30: =P1_Data!N28 | M30: =$L$2 | N30: =$L$3 | O30: =$L$4 | R30: =P1_Data!A26 | S30: =P1_Data!M26 | T30: =$I$5 | U30: =$I$7 | V30: =$I$8 | W30: =$I$9 | X30: =$I$10
A31: =P1_Data!A13 | B31: =P1_Data!M13 | C31: =$I$19 | D31: =$I$21 | E31: =$I$22 | F31: =IF(OR(B31>$I$21,B31<$I$22),B31,NA()) | G31: =IF(AND(B31<=$I$7,B31>=$I$8),1,0) | K31: =P1_Data!A29 | L31: =P1_Data!N29 | M31: =$L$2 | N31: =$L$3 | O31: =$L$4 | R31: =P1_Data!A27 | S31: =P1_Data!M27 | T31: =$I$5 | U31: =$I$7 | V31: =$I$8 | W31: =$I$9 | X31: =$I$10
A32: =P1_Data!A14 | B32: =P1_Data!M14 | C32: =$I$19 | D32: =$I$21 | E32: =$I$22 | F32: =IF(OR(B32>$I$21,B32<$I$22),B32,NA()) | G32: =IF(AND(B32<=$I$7,B32>=$I$8),1,0) | K32: =P1_Data!A30 | L32: =P1_Data!N30 | M32: =$L$2 | N32: =$L$3 | O32: =$L$4 | R32: =P1_Data!A28 | S32: =P1_Data!M28 | T32: =$I$5 | U32: =$I$7 | V32: =$I$8 | W32: =$I$9 | X32: =$I$10
A33: =P1_Data!A15 | B33: =P1_Data!M15 | C33: =$I$19 | D33: =$I$21 | E33: =$I$22 | F33: =IF(OR(B33>$I$21,B33<$I$22),B33,NA()) | G33: =IF(AND(B33<=$I$7,B33>=$I$8),1,0) | K33: =P1_Data!A31 | L33: =P1_Data!N31 | M33: =$L$2 | N33: =$L$3 | O33: =$L$4 | R33: =P1_Data!A29 | S33: =P1_Data!M29 | T33: =$I$5 | U33: =$I$7 | V33: =$I$8 | W33: =$I$9 | X33: =$I$10
A34: =P1_Data!A16 | B34: =P1_Data!M16 | C34: =$I$19 | D34: =$I$21 | E34: =$I$22 | F34: =IF(OR(B34>$I$21,B34<$I$22),B34,NA()) | G34: =IF(AND(B34<=$I$7,B34>=$I$8),1,0) | K34: =P1_Data!A32 | L34: =P1_Data!N32 | M34: =$L$2 | N34: =$L$3 | O34: =$L$4 | R34: =P1_Data!A30 | S34: =P1_Data!M30 | T34: =$I$5 | U34: =$I$7 | V34: =$I$8 | W34: =$I$9 | X34: =$I$10
A35: =P1_Data!A17 | B35: =P1_Data!M17 | C35: =$I$19 | D35: =$I$21 | E35: =$I$22 | F35: =IF(OR(B35>$I$21,B35<$I$22),B35,NA()) | G35: =IF(AND(B35<=$I$7,B35>=$I$8),1,0) | K35: =P1_Data!A33 | L35: =P1_Data!N33 | M35: =$L$2 | N35: =$L$3 | O35: =$L$4 | R35: =P1_Data!A31 | S35: =P1_Data!M31 | T35: =$I$5 | U35: =$I$7 | V35: =$I$8 | W35: =$I$9 | X35: =$I$10
A36: =P1_Data!A18 | B36: =P1_Data!M18 | C36: =$I$19 | D36: =$I$21 | E36: =$I$22 | F36: =IF(OR(B36>$I$21,B36<$I$22),B36,NA()) | G36: =IF(AND(B36<=$I$7,B36>=$I$8),1,0) | K36: =P1_Data!A34 | L36: =P1_Data!N34 | M36: =$L$2 | N36: =$L$3 | O36: =$L$4 | R36: =P1_Data!A32 | S36: =P1_Data!M32 | T36: =$I$5 | U36: =$I$7 | V36: =$I$8 | W36: =$I$9 | X36: =$I$10
... A38: =P1_Data!A20 | B38: =P1_Data!M20 | C38: =$I$19 | D38: =$I$21 | E38: =$I$22 | F38: =IF(OR(B38>$I$21,B38<$I$22),B38,NA()) | G38: =IF(AND(B38<=$I$7,B38>=$I$8),1,0) | K38: =P1_Data!A36 | L38: =P1_Data!N36 | M38: =$L$2 | N38: =$L$3 | O38: =$L$4 | R38: =P1_Data!A34 | S38: =P1_Data!M34 | T38: =$I$5 | U38: =$I$7 | V38: =$I$8 | W38: =$I$9 | X38: =$I$10
A39: =P1_Data!A21 | B39: =P1_Data!M21 | C39: =$I$19 | D39: =$I$21 | E39: =$I$22 | F39: =IF(OR(B39>$I$21,B39<$I$22),B39,NA()) | G39: =IF(AND(B39<=$I$7,B39>=$I$8),1,0) | K39: White | L39: =SUMIF(P1_Data!$G$7:$G$48,K39,P1_Data!$K$7:$K$48) | M39: =SUM($L$39:L39)/SUM($L$39:$L$45) | N39: =$L$3 | O39: =$L$4 | R39: =P1_Data!A35 | S39: =P1_Data!M35 | T39: =$I$5 | U39: =$I$7 | V39: =$I$8 | W39: =$I$9 | X39: =$I$10
A40: =P1_Data!A22 | B40: =P1_Data!M22 | C40: =$I$19 | D40: =$I$21 | E40: =$I$22 | F40: =IF(OR(B40>$I$21,B40<$I$22),B40,NA()) | G40: =IF(AND(B40<=$I$7,B40>=$I$8),1,0) | K40: Dark Blue | L40: =SUMIF(P1_Data!$G$7:$G$48,K40,P1_Data!$K$7:$K$48) | M40: =SUM($L$39:L40)/SUM($L$39:$L$45) | N40: =$L$3 | O40: =$L$4 | R40: =P1_Data!A36 | S40: =P1_Data!M36 | T40: =$I$5 | U40: =$I$7 | V40: =$I$8 | W40: =$I$9 | X40: =$I$10
A41: =P1_Data!A23 | B41: =P1_Data!M23 | C41: =$I$19 | D41: =$I$21 | E41: =$I$22 | F41: =IF(OR(B41>$I$21,B41<$I$22),B41,NA()) | G41: =IF(AND(B41<=$I$7,B41>=$I$8),1,0) | K41: Yellow | L41: =SUMIF(P1_Data!$G$7:$G$48,K41,P1_Data!$K$7:$K$48) | M41: =SUM($L$39:L41)/SUM($L$39:$L$45) | N41: =$L$3 | O41: =$L$4 | R41: =P1_Data!A37 | S41: =P1_Data!M37 | T41: =$I$5 | U41: =$I$7 | V41: =$I$8 | W41: =$I$9 | X41: =$I$10
...

Sheet P2_Data
A1: Process 2 — Assembly Run Data (colour-binned feed; first defect discards whole semi-assembly)
A2: Provenance: Pieces_Before_Defect_g, Defect_Found and Opportunity values are from process 2.pdf notes (cleaned where handwriting was unclear). Defect_Colour is reconstructed from aggregate totals. Time_Band/Pick_Order/sequence/cause labels are reconstructed classifications. g=acceptable pieces before defect (higher=better). u_i=Defect/Opportunity.
A6: Run_ID | B6: Data_Source_Type | C6: Phase | D6: Time_Band | E6: Pick_Order | F6: Colour_Sequence | G6: Defect_Colour | H6: Pieces_Before_Defect_g | I6: Pieces_Placed_Including_Defect | J6: Defect_Found_1_0 | K6: Assembly_Discarded_1_0 | L6: Completed_Assembly_1_0 | M6: Opportunity_Count | N6: u_i | O6: Assignable_Cause_Flag | P6: Assignable_Cause_Category | Q6: Assignable_Cause_Description | R6: Operator_Comment | S6: Analysis_Use | T6: Raw_Value_Source | U6: Defect_Colour_Source | V6: Classification_Source
A7: 1 | B7: Raw observed | C7: Phase 1 | D7: Early | E7: 4+1 | F7: Mixed→Red | G7: Red | H7: 4 | I7: =H7+J7 | J7: 1 | K7: 1 | L7: 0 | M7: =I7 | N7: =J7/M7 | O7: 0 | P7: None | Q7: Defect encountered mid-assembly | R7: Routine discard | S7: g-chart + u-chart + Pareto | T7: process 2.pdf notes (cleaned from notes where unclear) | U7: Reconstructed from aggregate colour totals | V7: Reconstructed classification
A8: 2 | B8: Raw observed | C8: Phase 1 | D8: Early | E8: 3+1 | F8: Mixed→Orange | G8: Orange | H8: 3 | I8: =H8+J8 | J8: 1 | K8: 1 | L8: 0 | M8: =I8 | N8: =J8/M8 | O8: 1 | P8: High-defect colour reached early | Q8: Orange (high-defect colour) picked at position 4, early discard | R8: Early high-defect-colour discard | S8: g-chart + u-chart + Pareto | T8: process 2.pdf notes (cleaned from notes where unclear) | U8: Reconstructed from aggregate colour totals | V8: Reconstructed classification
A9: 3 | B9: Raw observed | C9: Phase 1 | D9: Early | E9: 3+1 | F9: Mixed→Orange | G9: Orange | H9: 3 | I9: =H9+J9 | J9: 1 | K9: 1 | L9: 0 | M9: =I9 | N9: =J9/M9 | O9: 1 | P9: High-defect colour reached early | Q9: Orange (high-defect colour) picked at position 4, early discard | R9: Early high-defect-colour discard | S9: g-chart + u-chart + Pareto | T9: process 2.pdf notes (cleaned from notes where unclear) | U9: Reconstructed from aggregate colour totals | V9: Reconstructed classification
A10: 4 | B10: Raw observed | C10: Phase 1 | D10: Early | E10: 3+1 | F10: Mixed→Orange | G10: Orange | H10: 3 | I10: =H10+J10 | J10: 1 | K10: 1 | L10: 0 | M10: =I10 | N10: =J10/M10 | O10: 1 | P10: High-defect colour reached early | Q10: Orange (high-defect colour) picked at position 4, early discard | R10: Early high-defect-colour discard | S10: g-chart + u-chart + Pareto | T10: process 2.pdf notes (cleaned from notes where unclear) | U10: Reconstructed from aggregate colour totals | V10: Reconstructed classification
A11: 5 | B11: Raw observed | C11: Phase 1 | D11: Early | E11: 4+1 | F11: Mixed→Red | G11: Red | H11: 4 | I11: =H11+J11 | J11: 1 | K11: 1 | L11: 0 | M11: =I11 | N11: =J11/M11 | O11: 0 | P11: None | Q11: Defect encountered mid-assembly | R11: Routine discard | S11: g-chart + u-chart + Pareto | T11: process 2.pdf notes (cleaned from notes where unclear) | U11: Reconstructed from aggregate colour totals | V11: Reconstructed classification
A12: 6 | B12: Raw observed | C12: Phase 1 | D12: Early | E12: 3+1 | F12: Mixed→Orange | G12: Orange | H12: 3 | I12: =H12+J12 | J12: 1 | K12: 1 | L12: 0 | M12: =I12 | N12: =J12/M12 | O12: 1 | P12: High-defect colour reached early | Q12: Orange (high-defect colour) picked at position 4, early discard | R12: Early high-defect-colour discard | S12: g-chart + u-chart + Pareto | T12: process 2.pdf notes (cleaned from notes where unclear) | U12: Reconstructed from aggregate colour totals | V12: Reconstructed classification
A13: 7 | B13: Raw observed | C13: Phase 1 | D13: Early | E13: 6+1 | F13: Mixed→Dark Blue | G13: Dark Blue | H13: 6 | I13: =H13+J13 | J13: 1 | K13: 1 | L13: 0 | M13: =I13 | N13: =J13/M13 | O13: 0 | P13: None | Q13: Defect encountered mid-assembly | R13: Routine discard | S13: g-chart + u-chart + Pareto | T13: process 2.pdf notes (cleaned from notes where unclear) | U13: Reconstructed from aggregate colour totals | V13: Reconstructed classification
A14: 8 | B14: Raw observed | C14: Phase 1 | D14: Early | E14: 5+1 | F14: Mixed→Yellow | G14: Yellow | H14: 5 | I14: =H14+J14 | J14: 1 | K14: 1 | L14: 0 | M14: =I14 | N14: =J14/M14 | O14: 0 | P14: None | Q14: Defect encountered mid-assembly | R14: Routine discard | S14: g-chart + u-chart + Pareto | T14: process 2.pdf notes (cleaned from notes where unclear) | U14: Reconstructed from aggregate colour totals | V14: Reconstructed classification
A15: 9 | B15: Raw observed | C15: Phase 1 | D15: Early | E15: 4+1 | F15: Mixed→Red | G15: Red | H15: 4 | I15: =H15+J15 | J15: 1 | K15: 1 | L15: 0 | M15: =I15 | N15: =J15/M15 | O15: 0 | P15: None | Q15: Defect encountered mid-assembly | R15: Routine discard | S15: g-chart + u-chart + Pareto | T15: process 2.pdf notes (cleaned from notes where unclear) | U15: Reconstructed from aggregate colour totals | V15: Reconstructed classification
A16: 10 | B16: Raw observed | C16: Phase 1 | D16: Early | E16: 4+1 | F16: Mixed→Red | G16: Red | H16: 4 | I16: =H16+J16 | J16: 1 | K16: 1 | L16: 0 | M16: =I16 | N16: =J16/M16 | O16: 0 | P16: None | Q16: Defect encountered mid-assembly | R16: Routine discard | S16: g-chart + u-chart + Pareto | T16: process 2.pdf notes (cleaned from notes where unclear) | U16: Reconstructed from aggregate colour totals | V16: Reconstructed classification
A17: 11 | B17: Raw observed | C17: Phase 1 | D17: Middle | E17: 5+1 | F17: Mixed→Yellow | G17: Yellow | H17: 5 | I17: =H17+J17 | J17: 1 | K17: 1 | L17: 0 | M17: =I17 | N17: =J17/M17 | O17: 0 | P17: None | Q17: Defect encountered mid-assembly | R17: Routine discard | S17: g-chart + u-chart + Pareto | T17: process 2.pdf notes (cleaned from notes where unclear) | U17: Reconstructed from aggregate colour totals | V17: Reconstructed classification
A18: 12 | B18: Raw observed | C18: Phase 1 | D18: Middle | E18: 3+1 | F18: Mixed→Orange | G18: Orange | H18: 3 | I18: =H18+J18 | J18: 1 | K18: 1 | L18: 0 | M18: =I18 | N18: =J18/M18 | O18: 1 | P18: High-defect colour reached early | Q18: Orange (high-defect colour) picked at position 4, early discard | R18: Early high-defect-colour discard | S18: g-chart + u-chart + Pareto | T18: process 2.pdf notes (cleaned from notes where unclear) | U18: Reconstructed from aggregate colour totals | V18: Reconstructed classification
... A36: 30 | B36: Raw observed | C36: Phase 1 | D36: Late | E36: 4+1 | F36: Mixed→Red | G36: Red | H36: 4 | I36: =H36+J36 | J36: 1 | K36: 1 | L36: 0 | M36: =I36 | N36: =J36/M36 | O36: 0 | P36: None | Q36: Defect encountered mid-assembly | R36: Routine discard | S36: g-chart + u-chart + Pareto | T36: process 2.pdf notes (cleaned from notes where unclear) | U36: Reconstructed from aggregate colour totals | V36: Reconstructed classification
A37: TOTAL | J37: =SUM(J7:J36) | M37: =SUM(M7:M36)
A39: Legend: | B39: Raw observed | D39: Reconstructed classification

Sheet P2_Analysis
A1: Process 2 — u-chart + g-chart + Pareto | H1: PARAMETERS
H2: Total defects | I2: =SUM(P2_Data!J7:J36)
H3: Total opportunities | I3: =SUM(P2_Data!M7:M36)
H4: u_bar | I4: =I2/I3
H5: g_bar | I5: =AVERAGE(P2_Data!H7:H36)
H6: p_hat=1/(g_bar+1) | I6: =1/(I5+1)
A8: Run | B8: u_i | C8: u_bar | D8: UCL_3σ | E8: LCL_3σ | R8: Run | S8: g_i
A9: =P2_Data!A7 | B9: =P2_Data!N7 | C9: =$I$4 | D9: =$I$4+3*SQRT($I$4/P2_Data!M7) | E9: =MAX(0,$I$4-3*SQRT($I$4/P2_Data!M7)) | R9: =P2_Data!A7 | S9: =P2_Data!H7
A10: =P2_Data!A8 | B10: =P2_Data!N8 | C10: =$I$4 | D10: =$I$4+3*SQRT($I$4/P2_Data!M8) | E10: =MAX(0,$I$4-3*SQRT($I$4/P2_Data!M8)) | H10: g-chart (geometric approx., higher = better) | R10: =P2_Data!A8 | S10: =P2_Data!H8
A11: =P2_Data!A9 | B11: =P2_Data!N9 | C11: =$I$4 | D11: =$I$4+3*SQRT($I$4/P2_Data!M9) | E11: =MAX(0,$I$4-3*SQRT($I$4/P2_Data!M9)) | H11: Run | I11: g_i | J11: g_bar | K11: UCL_3σ | L11: LCL_3σ | M11: Practical_Max_7 | R11: =P2_Data!A9 | S11: =P2_Data!H9
A12: =P2_Data!A10 | B12: =P2_Data!N10 | C12: =$I$4 | D12: =$I$4+3*SQRT($I$4/P2_Data!M10) | E12: =MAX(0,$I$4-3*SQRT($I$4/P2_Data!M10)) | H12: =P2_Data!A7 | I12: =P2_Data!H7 | J12: =$I$5 | K12: =MIN(7,$I$5+3*SQRT((1-$I$6)/$I$6^2)) | L12: =MAX(0,$I$5-3*SQRT((1-$I$6)/$I$6^2)) | M12: 7 | R12: =P2_Data!A10 | S12: =P2_Data!H10
A13: =P2_Data!A11 | B13: =P2_Data!N11 | C13: =$I$4 | D13: =$I$4+3*SQRT($I$4/P2_Data!M11) | E13: =MAX(0,$I$4-3*SQRT($I$4/P2_Data!M11)) | H13: =P2_Data!A8 | I13: =P2_Data!H8 | J13: =$I$5 | K13: =MIN(7,$I$5+3*SQRT((1-$I$6)/$I$6^2)) | L13: =MAX(0,$I$5-3*SQRT((1-$I$6)/$I$6^2)) | M13: 7 | R13: =P2_Data!A11 | S13: =P2_Data!H11
A14: =P2_Data!A12 | B14: =P2_Data!N12 | C14: =$I$4 | D14: =$I$4+3*SQRT($I$4/P2_Data!M12) | E14: =MAX(0,$I$4-3*SQRT($I$4/P2_Data!M12)) | H14: =P2_Data!A9 | I14: =P2_Data!H9 | J14: =$I$5 | K14: =MIN(7,$I$5+3*SQRT((1-$I$6)/$I$6^2)) | L14: =MAX(0,$I$5-3*SQRT((1-$I$6)/$I$6^2)) | M14: 7 | R14: =P2_Data!A12 | S14: =P2_Data!H12
A15: =P2_Data!A13 | B15: =P2_Data!N13 | C15: =$I$4 | D15: =$I$4+3*SQRT($I$4/P2_Data!M13) | E15: =MAX(0,$I$4-3*SQRT($I$4/P2_Data!M13)) | H15: =P2_Data!A10 | I15: =P2_Data!H10 | J15: =$I$5 | K15: =MIN(7,$I$5+3*SQRT((1-$I$6)/$I$6^2)) | L15: =MAX(0,$I$5-3*SQRT((1-$I$6)/$I$6^2)) | M15: 7 | R15: =P2_Data!A13 | S15: =P2_Data!H13
A16: =P2_Data!A14 | B16: =P2_Data!N14 | C16: =$I$4 | D16: =$I$4+3*SQRT($I$4/P2_Data!M14) | E16: =MAX(0,$I$4-3*SQRT($I$4/P2_Data!M14)) | H16: =P2_Data!A11 | I16: =P2_Data!H11 | J16: =$I$5 | K16: =MIN(7,$I$5+3*SQRT((1-$I$6)/$I$6^2)) | L16: =MAX(0,$I$5-3*SQRT((1-$I$6)/$I$6^2)) | M16: 7 | R16: =P2_Data!A14 | S16: =P2_Data!H14
A17: =P2_Data!A15 | B17: =P2_Data!N15 | C17: =$I$4 | D17: =$I$4+3*SQRT($I$4/P2_Data!M15) | E17: =MAX(0,$I$4-3*SQRT($I$4/P2_Data!M15)) | H17: =P2_Data!A12 | I17: =P2_Data!H12 | J17: =$I$5 | K17: =MIN(7,$I$5+3*SQRT((1-$I$6)/$I$6^2)) | L17: =MAX(0,$I$5-3*SQRT((1-$I$6)/$I$6^2)) | M17: 7 | R17: =P2_Data!A15 | S17: =P2_Data!H15
A18: =P2_Data!A16 | B18: =P2_Data!N16 | C18: =$I$4 | D18: =$I$4+3*SQRT($I$4/P2_Data!M16) | E18: =MAX(0,$I$4-3*SQRT($I$4/P2_Data!M16)) | H18: =P2_Data!A13 | I18: =P2_Data!H13 | J18: =$I$5 | K18: =MIN(7,$I$5+3*SQRT((1-$I$6)/$I$6^2)) | L18: =MAX(0,$I$5-3*SQRT((1-$I$6)/$I$6^2)) | M18: 7 | R18: =P2_Data!A16 | S18: =P2_Data!H16
A19: =P2_Data!A17 | B19: =P2_Data!N17 | C19: =$I$4 | D19: =$I$4+3*SQRT($I$4/P2_Data!M17) | E19: =MAX(0,$I$4-3*SQRT($I$4/P2_Data!M17)) | H19: =P2_Data!A14 | I19: =P2_Data!H14 | J19: =$I$5 | K19: =MIN(7,$I$5+3*SQRT((1-$I$6)/$I$6^2)) | L19: =MAX(0,$I$5-3*SQRT((1-$I$6)/$I$6^2)) | M19: 7 | R19: =P2_Data!A17 | S19: =P2_Data!H17
A20: =P2_Data!A18 | B20: =P2_Data!N18 | C20: =$I$4 | D20: =$I$4+3*SQRT($I$4/P2_Data!M18) | E20: =MAX(0,$I$4-3*SQRT($I$4/P2_Data!M18)) | H20: =P2_Data!A15 | I20: =P2_Data!H15 | J20: =$I$5 | K20: =MIN(7,$I$5+3*SQRT((1-$I$6)/$I$6^2)) | L20: =MAX(0,$I$5-3*SQRT((1-$I$6)/$I$6^2)) | M20: 7 | R20: =P2_Data!A18 | S20: =P2_Data!H18
A21: =P2_Data!A19 | B21: =P2_Data!N19 | C21: =$I$4 | D21: =$I$4+3*SQRT($I$4/P2_Data!M19) | E21: =MAX(0,$I$4-3*SQRT($I$4/P2_Data!M19)) | H21: =P2_Data!A16 | I21: =P2_Data!H16 | J21: =$I$5 | K21: =MIN(7,$I$5+3*SQRT((1-$I$6)/$I$6^2)) | L21: =MAX(0,$I$5-3*SQRT((1-$I$6)/$I$6^2)) | M21: 7 | R21: =P2_Data!A19 | S21: =P2_Data!H19
A22: =P2_Data!A20 | B22: =P2_Data!N20 | C22: =$I$4 | D22: =$I$4+3*SQRT($I$4/P2_Data!M20) | E22: =MAX(0,$I$4-3*SQRT($I$4/P2_Data!M20)) | H22: =P2_Data!A17 | I22: =P2_Data!H17 | J22: =$I$5 | K22: =MIN(7,$I$5+3*SQRT((1-$I$6)/$I$6^2)) | L22: =MAX(0,$I$5-3*SQRT((1-$I$6)/$I$6^2)) | M22: 7 | R22: =P2_Data!A20 | S22: =P2_Data!H20
A23: =P2_Data!A21 | B23: =P2_Data!N21 | C23: =$I$4 | D23: =$I$4+3*SQRT($I$4/P2_Data!M21) | E23: =MAX(0,$I$4-3*SQRT($I$4/P2_Data!M21)) | H23: =P2_Data!A18 | I23: =P2_Data!H18 | J23: =$I$5 | K23: =MIN(7,$I$5+3*SQRT((1-$I$6)/$I$6^2)) | L23: =MAX(0,$I$5-3*SQRT((1-$I$6)/$I$6^2)) | M23: 7 | R23: =P2_Data!A21 | S23: =P2_Data!H21
... A38: =P2_Data!A36 | B38: =P2_Data!N36 | C38: =$I$4 | D38: =$I$4+3*SQRT($I$4/P2_Data!M36) | E38: =MAX(0,$I$4-3*SQRT($I$4/P2_Data!M36)) | H38: =P2_Data!A33 | I38: =P2_Data!H33 | J38: =$I$5 | K38: =MIN(7,$I$5+3*SQRT((1-$I$6)/$I$6^2)) | L38: =MAX(0,$I$5-3*SQRT((1-$I$6)/$I$6^2)) | M38: 7 | R38: =P2_Data!A36 | S38: =P2_Data!H36
H39: =P2_Data!A34 | I39: =P2_Data!H34 | J39: =$I$5 | K39: =MIN(7,$I$5+3*SQRT((1-$I$6)/$I$6^2)) | L39: =MAX(0,$I$5-3*SQRT((1-$I$6)/$I$6^2)) | M39: 7
H40: =P2_Data!A35 | I40: =P2_Data!H35 | J40: =$I$5 | K40: =MIN(7,$I$5+3*SQRT((1-$I$6)/$I$6^2)) | L40: =MAX(0,$I$5-3*SQRT((1-$I$6)/$I$6^2)) | M40: 7
H41: =P2_Data!A36 | I41: =P2_Data!H36 | J41: =$I$5 | K41: =MIN(7,$I$5+3*SQRT((1-$I$6)/$I$6^2)) | L41: =MAX(0,$I$5-3*SQRT((1-$I$6)/$I$6^2)) | M41: 7
H56: g-chart boundary note
H57: The calculated geometric UCL exceeds the physical maximum of seven pieces. Therefore, the g-chart is interpreted as a relative monitoring chart, while the practical upper boundary is seven pieces, representing a completed defect-free assembly. (UCL is capped at 7 in the table for realism.)
A60: PARETO — Process 2 defects by colour
A61: Colour | B61: Defects | C61: Cum % | D61: 80% line
A62: Orange | B62: =COUNTIF(P2_Data!$G$7:$G$36,A62) | C62: =SUM($B$62:B62)/30 | D62: 0.8 | H62: Western Electric Rule Checks (u-chart)
A63: Red | B63: =COUNTIF(P2_Data!$G$7:$G$36,A63) | C63: =SUM($B$62:B63)/30 | D63: 0.8 | H63: Rule | I63: Description | J63: Triggered?
A64: Yellow | B64: =COUNTIF(P2_Data!$G$7:$G$36,A64) | C64: =SUM($B$62:B64)/30 | D64: 0.8 | H64: Rule 1 | I64: 1 point beyond 3σ | J64: =IF(SUMPRODUCT((B9:B38>D9:D38)*1)>0,"YES","No")
A65: Dark Blue | B65: =COUNTIF(P2_Data!$G$7:$G$36,A65) | C65: =SUM($B$62:B65)/30 | D65: 0.8 | H65: Rule 2 | I65: 2 of 3 beyond 2σ | J65: Manual review
A66: White | B66: =COUNTIF(P2_Data!$G$7:$G$36,A66) | C66: =SUM($B$62:B66)/30 | D66: 0.8 | H66: Rule 4 | I66: 8 consecutive one side | J66: =IF(MAX(FREQUENCY(IF(B9:B38>C9:C38,ROW(B9:B38)),IF(B9:B38<=C9:C38,ROW(B9:B38))))>=8,"YES","No")
A67: Light Blue | B67: =COUNTIF(P2_Data!$G$7:$G$36,A67) | C67: =SUM($B$62:B67)/30 | D67: 0.8
A68: Green | B68: =COUNTIF(P2_Data!$G$7:$G$36,A68) | C68: =SUM($B$62:B68)/30 | D68: 0.8
A85: Interpretation: Process 2 averages g≈4 acceptable pieces before a defect forces a discard, so most runs fail before the full seven-piece figurine is completed. The u-chart shows defects-per-opportunity scattered around ū with run-specific limits (limits widen for shorter runs). Pareto shows Orange and Red dominate the discard-causing defects, mirroring Process 1 and pointing to the same supplier/colour assignable cause. A higher g is operationally favourable; a hypothetical full assembly (g=7) would be statistically high but a good outcome, not an alarm.
A95: Assignable Cause Analysis — Process 2
A96: Sample_or_Run | B96: Signal_Observed | C96: Possible_Assignable_Cause | D96: Evidence_From_Data | E96: Retain_or_Exclude | F96: Reason | G96: Recommended_Action
...

Sheet Comparison_DPMO_Cost
A1: Process Comparison — DPMO, Hypothesis Test, Cost & Throughput
A3: 1. DPMO & 2-sigma capability | F3: 3. Cost & Throughput
A4: Metric | B4: Process 1 | C4: Process 2 | D4: Better | F4: Assumptions (completed assemblies in notes are not fully captured; uncertainty flagged where needed)
A5: Total defects | B5: =SUM(P1_Data!K7:K48) | C5: =SUM(P2_Data!J7:J36) | F5: Piece cost (R) | G5: 2
A6: Total opportunities | B6: =SUM(P1_Data!J7:J48) | C6: =SUM(P2_Data!M7:M36) | F6: Board cost (R) | G6: 5
A7: Defect rate (p) | B7: =B5/B6 | C7: =C5/C6 | D7: =IF(B7<C7,"P1","P2") | F7: Discard cost (R) | G7: 20
A8: DPMO | B8: =B7*1000000 | C8: =C7*1000000 | D8: =IF(B8<C8,"P1","P2") | F8: Selling price (R) | G8: 25
A9: 2-sigma benchmark | B9: 308537 | C9: 308537 | F9: P1 completed assemblies | G9: =IF(COUNTA(P1_Data!P7:P48)=0,"uncertain",SUM(P1_Data!P7:P48))
A10: Meets 2-sigma? (DPMO<bench) | B10: =IF(B8<B9,"YES","NO") | C10: =IF(C8<C9,"YES","NO") | F10: P2 completed assemblies | G10: =IF(COUNTA(P2_Data!L7:L36)=0,"uncertain",SUM(P2_Data!L7:L36))
F11: P1 time (min) | G11: 15
A12: Process 1 fails the 2-sigma benchmark (DPMO above 308,537); Process 2 passes (DPMO below 308,537). | F12: P2 time (min) | G12: 9.21
A14: 2. Two-proportion z-test (H0: p1=p2 vs H1: p1≠p2)
A15: x1 (P1 defects) | B15: =B5 | F15: Cost / output | G15: Process 1 | H15: Process 2
A16: n1 (P1 pieces) | B16: =B6 | F16: Pieces consumed | H16: =B6 | I16: =C6
A17: x2 (P2 defects) | B17: =C5 | F17: Material (pieces) cost | H17: =H16*G5 | I17: =I16*G5
A18: n2 (P2 opp.) | B18: =C6 | F18: Discard cost | H18: =0 | I18: =SUM(P2_Data!K7:K36)*G7
A19: p1 | B19: =B15/B16 | F19: Revenue (completed×price) | H19: =IF(ISNUMBER(G9),G9*G8,0) | I19: =IF(ISNUMBER(G10),G10*G8,0)
A20: p2 | B20: =B17/B18 | F20: Total cost | H20: =H17+H18 | I20: =I17+I18
A21: pooled p | B21: =(B15+B17)/(B16+B18) | F21: Profit / (loss) | H21: =H19-H20 | I21: =I19-I20
A22: SE | B22: =SQRT(B21*(1-B21)*(1/B16+1/B18)) | F22: Throughput (assemblies) | H22: =IF(ISNUMBER(G9),G9,"uncertain") | I22: =IF(ISNUMBER(G10),G10,"uncertain")
A23: z | B23: =(B19-B20)/B22 | F23: Defect rate | H23: =B7 | I23: =C7
A24: p-value (two-tailed) | B24: =2*(1-NORMSDIST(ABS(B23)))
A25: Decision (α=0.05) | B25: =IF(B24<0.05,"Reject H0","Fail to reject H0")
A26: Interpretation: with p1≈0.36 and p2≈0.20, the two-tailed z-test (z≈3.36, p≈0.0008) rejects H0 — the two processes differ significantly in defect proportion, with Process 2 markedly lower. Opportunity for P2 is defined as pieces placed including the defective piece (g+1 per discarded run), giving 151 opportunities over 30 runs.
A40: Chart data
A41: Metric | B41: Process 1 | C41: Process 2
A42: DPMO | B42: =B8 | C42: =C8
A43: Defect rate | B43: =B7 | C43: =C7
A44: Total cost (R) | B44: =H20 | C44: =I20

Sheet Dashboard_Report_Tables
A1: Tangra Inc. — SPC Dashboard & Report Tables
A2: Author: Nthabiseng Maoka (30224926)
A4: P1 defect rate | D4: P2 defect rate | G4: P1 DPMO
A5: =Comparison_DPMO_Cost!B7 | D5: =Comparison_DPMO_Cost!C7 | G5: =Comparison_DPMO_Cost!B8
A7: P2 DPMO | D7: 2σ P1 | G7: 2σ P2
A8: =Comparison_DPMO_Cost!C8 | D8: =Comparison_DPMO_Cost!B10 | G8: =Comparison_DPMO_Cost!C10
A10: z-test p-value | D10: Top defect colour | G10: Recommended process
A11: =Comparison_DPMO_Cost!B24 | D11: =INDEX(P1_Analysis!AA11:AA17,MATCH(MAX(P1_Analysis!AB11:AB17),P1_Analysis!AB11:AB17,0)) | F11: Chart selection justification | G11: =IF(Comparison_DPMO_Cost!C8<Comparison_DPMO_Cost!B8,"Process 2","Process 1")
A12: Criterion | B12: Process 1 | C12: Process 2 | D12: Better | F12: Chart | G12: Process | H12: Justification
A13: Defect rate | B13: =Comparison_DPMO_Cost!B7 | C13: =Comparison_DPMO_Cost!C7 | D13: =IF(B13<C13,"P1","P2") | F13: p-chart | G13: P1 | H13: fixed n=5, proportion defective — primary rubric chart
A14: DPMO | B14: =Comparison_DPMO_Cost!B8 | C14: =Comparison_DPMO_Cost!C8 | D14: =IF(B14<C14,"P1","P2") | F14: np-chart | G14: P1 | H14: count defective valid (n constant); confirms p-chart
A15: Meets 2σ? | B15: =Comparison_DPMO_Cost!B10 | C15: =Comparison_DPMO_Cost!C10 | D15: — | F15: Pareto | G15: both | H15: rank colours to target assignable causes
A16: Statistically stable? | B16: Round-2 limits show colour-driven OOC | C16: Limits run-specific (u-chart) | D16: — | F16: u-chart | G16: P2 | H16: defects per varying opportunity size
A17: Throughput (completed) | B17: =Comparison_DPMO_Cost!G9 | C17: =Comparison_DPMO_Cost!G10 | D17: — | F17: g-chart | G17: P2 | H17: pieces before defect; higher = better
A20: Defect vs Defective | F20: Assignable causes (evidence-based)
A21: Term | B21: Meaning | F21: • Supplier/colour concentration — White, Yellow, Red, Orange dominate defects in both processes.
A22: Defect | B22: one nonconforming feature on a piece | F22: • Light Blue & Green show zero defects — possible different supplier/bin or inspection focus change.
A23: Defective piece | B23: a piece that cannot be used | F23: • Process 2 discards whole assemblies on first defect — early defects (low g) drive cost.
A24: Defective assembly | B24: a figurine that cannot ship
A25: Non-defective assembly | B25: complete, all 7 pieces fit
A28: Final recommendation
A29: Final recommendation: Process 2 is currently preferred because it has a lower defect rate and lower DPMO, and it passes the 2-sigma benchmark while Process 1 fails. However, both processes show colour-linked assignable causes (especially Orange/Red/White), so supplier-quality correction is required before full rollout. Report that completed-assembly output in the source notes is not fully captured and was treated conservatively in cost interpretation.
A40: Assignable causes summary
A41: • Supplier/colour concentration: White, Dark Blue, Yellow, Red, Orange dominate defects in BOTH processes (Pareto).
A42: • Light Blue & Green: zero defects in P1 — benchmark colours / different supplier or bin.
A43: • Process 2 early discards driven by high-defect colours (Orange/Red) reached early in the pick order.
A44: • No single-point 3σ outlier in P1 (n=5 caps limits) — cause is between-colour, not a rogue subgroup.
