Workbook

Sheet README_GA4
A1: INGB413 GA — Tangra Inc. Quality Assurance Workbook
A2: Author: Nthabiseng Maoka (30224926)
A3: Subject: Statistical Process Control & Process Capability — comparison of two assembly processes
A4: Prepared: 2026-05-29
A6: Purpose
A7: This workbook analyses defect data from two tangram-assembly processes at Tangra Inc. using attribute control charts, performs a two-round (Phase 1) p-chart study, compares the two processes via a two-proportion z-test and process-capability (DPMO) metrics, and derives a cost/throughput-based recommendation.
A11: Data Integrity Note
A12: All values are transcribed from the recorded process observations (process_1.pdf / process_2.pdf, as captured in the supplied data file). No defect counts were invented or inflated. Each P1/P2 row carries a Data_Source_Type label. "Raw observed" = directly recorded; "Cleaned from notes" = same observation, tidied into tabular form. No synthetic rows are presented as observed data.
A16: Defect vs Defective
A17: Term | B17: Definition (operational)
A18: Defect | B18: One nonconforming feature on a puzzle piece (chip, warp, wrong cut, colour fault).
A19: Defective piece | B19: A single puzzle piece that cannot be used in assembly.
A20: Defective assembly | B20: A figurine / semi-assembly that cannot be shipped because a defective piece was used.
A21: Non-defective assembly | B21: A complete figurine with all seven pieces fitting correctly.
A23: Chart Selection Logic
A24: Process | B24: Data type | C24: Chart | D24: Why
A25: P1 | B25: Attribute, fixed n=5 | C25: p-chart | D25: Proportion defective per sample; primary rubric chart.
A26: P1 | B26: Attribute, fixed n=5 | C26: np-chart | D26: Count defective; valid because n is constant. Confirms p-chart.
A27: P1 | B27: Categorical | C27: Pareto | D27: Ranks defect contribution by colour to target assignable causes.
A28: P2 | B28: Count, varying opportunity | C28: u-chart | D28: Defects per varying pieces-placed opportunity.
A29: P2 | B29: Geometric | C29: g-chart (approx.) | D29: Acceptable pieces before first defect; higher = better.
A30: Both | B30: Proportions | C30: 2-prop z-test | D30: Tests whether the two processes differ in defect rate.
A33: GA4 Alignment
A34: GA4 component | B34: How workbook addresses it | C34: Evidence sheet
A35: Research method | B35: Structured attribute sampling (n=5) and run-based assembly sampling; two-phase SPC method. | C35: P1_Data, P2_Data
A36: Research-based knowledge | B36: Montgomery SPC formulae for p/np/u charts and capability; 2-sigma DPMO benchmark. | C36: P1_Analysis, Comparison
A37: Design of experiments | B37: Two competing processes observed under comparable conditions; defined defect criteria. | C37: README, P1/P2_Data
A38: Analysis & interpretation | B38: Two-round p-chart, control-limit calc, Pareto, z-test, cost/throughput. | C38: P1/P2_Analysis, Comparison
A39: Synthesis of conclusions | B39: Integrated recommendation from stability, DPMO, cost and throughput. | C39: Dashboard_Report_Tables
A41: Key Assumptions
A42: • Sample size for Process 1 is fixed at n = 5 pieces.
A43: • Process 1 total: 76 defects over 210 inspected pieces (42 samples).
A44: • Process 2: 30 assembly runs, 30 defect events over 121 pieces-placed opportunities.
A45: • Cost inputs: piece R2, board R5, discarded semi-assembly R20, selling price R25.
A46: • 2-sigma capability benchmark = 308,537 DPMO.
A47: • Control limits use 3-sigma (action) with 1- and 2-sigma zones shown for context.

Sheet P1_Data
A1: Process 1 — Inspection Data (bulk feed, n=5, defectives removed before assembly)
A2: Provenance: Defects_d, Colour, n = Raw observed (transcribed counts). Time_Band/Process_Step/Sampling_Mode/Shape/Supplier_or_Bin/Specific_Defect_Type/Assignable_Cause = Reconstructed classification (derived, NOT per-piece recorded). p_i, np_i, Nondefective_Count = formula. Defect criterion: chipped/warped/mis-cut/off-colour piece unusable. p_i=Defects_d/5.
A6: Sample_ID | B6: Data_Source_Type | C6: Phase | D6: Time_Band | E6: Process_Step | F6: Sampling_Mode | G6: Colour | H6: Shape | I6: Supplier_or_Bin | J6: n | K6: Defects_d | L6: Nondefective_Count | M6: p_i | N6: np_i | O6: Inspection_Result | P6: Final_Assembly_ID | Q6: Final_Product_Defective | R6: Defects_in_Final_Assembly | S6: Specific_Defect_Type | T6: Assignable_Cause_Flag | U6: Assignable_Cause_Category | V6: Assignable_Cause_Description | W6: Operator_Comment | X6: Analysis_Use
A7: 1 | B7: Raw observed | C7: Phase 1 | D7: Early | E7: Incoming inspection | F7: Colour-grouped sample | G7: Red | H7: Large triangle | I7: Supplier A | J7: 5 | K7: 3 | L7: =J7-K7 -> 2 | M7: =K7/J7 -> 0.6 | N7: =K7 -> 3 | O7: =IF(K7=0,"Accept",IF(K7>=3,"Reject batch","Rework")) -> Reject batch | S7: See colour-level note | T7: 0 | U7: None | V7: Within expected colour variation | W7: Routine | X7: SPC + Pareto
A8: 2 | B8: Raw observed | C8: Phase 1 | D8: Early | E8: Incoming inspection | F8: Colour-grouped sample | G8: Red | H8: Large triangle | I8: Supplier A | J8: 5 | K8: 0 | L8: =J8-K8 -> 5 | M8: =K8/J8 -> 0 | N8: =K8 -> 0 | O8: =IF(K8=0,"Accept",IF(K8>=3,"Reject batch","Rework")) -> Accept | S8: None | T8: 0 | U8: None | V8: Within expected colour variation | W8: Routine | X8: SPC + Pareto
A9: 3 | B9: Raw observed | C9: Phase 1 | D9: Early | E9: Incoming inspection | F9: Colour-grouped sample | G9: Red | H9: Large triangle | I9: Supplier A | J9: 5 | K9: 4 | L9: =J9-K9 -> 1 | M9: =K9/J9 -> 0.8 | N9: =K9 -> 4 | O9: =IF(K9=0,"Accept",IF(K9>=3,"Reject batch","Rework")) -> Reject batch | S9: See colour-level note | T9: 1 | U9: Supplier-related defect concentration | V9: Red block shows elevated defect rate; possible supplier/bin issue | W9: High-defect colour batch | X9: SPC + Pareto
A10: 4 | B10: Raw observed | C10: Phase 1 | D10: Early | E10: Incoming inspection | F10: Colour-grouped sample | G10: Red | H10: Large triangle | I10: Supplier A | J10: 5 | K10: 2 | L10: =J10-K10 -> 3 | M10: =K10/J10 -> 0.4 | N10: =K10 -> 2 | O10: =IF(K10=0,"Accept",IF(K10>=3,"Reject batch","Rework")) -> Rework | S10: See colour-level note | T10: 0 | U10: None | V10: Within expected colour variation | W10: Routine | X10: SPC + Pareto
A11: 5 | B11: Raw observed | C11: Phase 1 | D11: Early | E11: Incoming inspection | F11: Colour-grouped sample | G11: Red | H11: Large triangle | I11: Supplier A | J11: 5 | K11: 3 | L11: =J11-K11 -> 2 | M11: =K11/J11 -> 0.6 | N11: =K11 -> 3 | O11: =IF(K11=0,"Accept",IF(K11>=3,"Reject batch","Rework")) -> Reject batch | S11: See colour-level note | T11: 0 | U11: None | V11: Within expected colour variation | W11: Routine | X11: SPC + Pareto
A12: 6 | B12: Raw observed | C12: Phase 1 | D12: Early | E12: Incoming inspection | F12: Colour-grouped sample | G12: Red | H12: Large triangle | I12: Supplier A | J12: 5 | K12: 2 | L12: =J12-K12 -> 3 | M12: =K12/J12 -> 0.4 | N12: =K12 -> 2 | O12: =IF(K12=0,"Accept",IF(K12>=3,"Reject batch","Rework")) -> Rework | S12: See colour-level note | T12: 0 | U12: None | V12: Within expected colour variation | W12: Routine | X12: SPC + Pareto
A13: 7 | B13: Raw observed | C13: Phase 1 | D13: Early | E13: Incoming inspection | F13: Colour-grouped sample | G13: Yellow | H13: Medium triangle | I13: Supplier A | J13: 5 | K13: 4 | L13: =J13-K13 -> 1 | M13: =K13/J13 -> 0.8 | N13: =K13 -> 4 | O13: =IF(K13=0,"Accept",IF(K13>=3,"Reject batch","Rework")) -> Reject batch | S13: See colour-level note | T13: 1 | U13: Supplier-related defect concentration | V13: Yellow block shows elevated defect rate; possible supplier/bin issue | W13: High-defect colour batch | X13: SPC + Pareto
A14: 8 | B14: Raw observed | C14: Phase 1 | D14: Early | E14: Incoming inspection | F14: Colour-grouped sample | G14: Yellow | H14: Medium triangle | I14: Supplier A | J14: 5 | K14: 3 | L14: =J14-K14 -> 2 | M14: =K14/J14 -> 0.6 | N14: =K14 -> 3 | O14: =IF(K14=0,"Accept",IF(K14>=3,"Reject batch","Rework")) -> Reject batch | S14: See colour-level note | T14: 0 | U14: None | V14: Within expected colour variation | W14: Routine | X14: SPC + Pareto
A15: 9 | B15: Raw observed | C15: Phase 1 | D15: Early | E15: Incoming inspection | F15: Colour-grouped sample | G15: Yellow | H15: Medium triangle | I15: Supplier A | J15: 5 | K15: 3 | L15: =J15-K15 -> 2 | M15: =K15/J15 -> 0.6 | N15: =K15 -> 3 | O15: =IF(K15=0,"Accept",IF(K15>=3,"Reject batch","Rework")) -> Reject batch | S15: See colour-level note | T15: 0 | U15: None | V15: Within expected colour variation | W15: Routine | X15: SPC + Pareto
A16: 10 | B16: Raw observed | C16: Phase 1 | D16: Early | E16: Incoming inspection | F16: Colour-grouped sample | G16: Yellow | H16: Medium triangle | I16: Supplier A | J16: 5 | K16: 1 | L16: =J16-K16 -> 4 | M16: =K16/J16 -> 0.2 | N16: =K16 -> 1 | O16: =IF(K16=0,"Accept",IF(K16>=3,"Reject batch","Rework")) -> Rework | S16: See colour-level note | T16: 0 | U16: None | V16: Within expected colour variation | W16: Routine | X16: SPC + Pareto
A17: 11 | B17: Raw observed | C17: Phase 1 | D17: Early | E17: Incoming inspection | F17: Colour-grouped sample | G17: Yellow | H17: Medium triangle | I17: Supplier A | J17: 5 | K17: 2 | L17: =J17-K17 -> 3 | M17: =K17/J17 -> 0.4 | N17: =K17 -> 2 | O17: =IF(K17=0,"Accept",IF(K17>=3,"Reject batch","Rework")) -> Rework | S17: See colour-level note | T17: 0 | U17: None | V17: Within expected colour variation | W17: Routine | X17: SPC + Pareto
A18: 12 | B18: Raw observed | C18: Phase 1 | D18: Early | E18: Incoming inspection | F18: Colour-grouped sample | G18: Yellow | H18: Medium triangle | I18: Supplier A | J18: 5 | K18: 1 | L18: =J18-K18 -> 4 | M18: =K18/J18 -> 0.2 | N18: =K18 -> 1 | O18: =IF(K18=0,"Accept",IF(K18>=3,"Reject batch","Rework")) -> Rework | S18: See colour-level note | T18: 0 | U18: None | V18: Within expected colour variation | W18: Routine | X18: SPC + Pareto
... A48: 42 | B48: Raw observed | C48: Phase 1 | D48: Late | E48: Incoming inspection | F48: Colour-grouped sample | G48: Orange | H48: Square | I48: Supplier B | J48: 5 | K48: 3 | L48: =J48-K48 -> 2 | M48: =K48/J48 -> 0.6 | N48: =K48 -> 3 | O48: =IF(K48=0,"Accept",IF(K48>=3,"Reject batch","Rework")) -> Reject batch | S48: See colour-level note | T48: 0 | U48: None | V48: Within expected colour variation | W48: Routine | X48: SPC + Pareto
A49: TOTAL | J49: =SUM(J7:J48) -> 210 | K49: =SUM(K7:K48) -> 76 | L49: =SUM(L7:L48) -> 134
A51: Legend: | B51: Raw observed | C51: Reconstructed classification | E51: Assignable-cause flagged

Sheet P1_Analysis
A1: Process 1 — p-chart Analysis (Phase 1: Round 1 → remove OOC → Round 2) + np-chart + Pareto | H1: ROUND 1 PARAMETERS | K1: np-CHART
H2: Total defects | I2: =SUM(P1_Data!K7:K48) -> 76 | K2: np_bar | L2: =$I$4*$I$5 -> 1.8095238
A3: Sample | B3: p_i | C3: CL (p̄) | D3: UCL_3σ | E3: LCL_3σ | F3: Out_of_Control | H3: Total pieces | I3: =SUM(P1_Data!J7:J48) -> 210 | K3: UCL 3s | L3: =$L$2+3*SQRT($I$4*$I$5*(1-$I$5)) -> 5.033161
A4: =P1_Data!A7 -> 1 | B4: =P1_Data!M7 -> 0.6 | C4: =$I$5 -> 0.36190476 | D4: =$I$7 -> 1 | E4: =$I$8 -> 0 | F4: =IF(OR(B4>$I$7,B4<$I$8),B4,NA()) -> #N/A | G4: =IF(AND(B4<=$I$7,B4>=$I$8),1,0) -> 1 | H4: n | I4: 5 | K4: LCL 3s | L4: =MAX(0,$L$2-3*SQRT($I$4*$I$5*(1-$I$5))) -> 0
A5: =P1_Data!A8 -> 2 | B5: =P1_Data!M8 -> 0 | C5: =$I$5 -> 0.36190476 | D5: =$I$7 -> 1 | E5: =$I$8 -> 0 | F5: =IF(OR(B5>$I$7,B5<$I$8),B5,NA()) -> #N/A | G5: =IF(AND(B5<=$I$7,B5>=$I$8),1,0) -> 1 | H5: p_bar | I5: =I2/I3 -> 0.36190476 | K5: UCL 2s | L5: =$L$2+2*SQRT($I$4*$I$5*(1-$I$5)) -> 3.9586153
A6: =P1_Data!A9 -> 3 | B6: =P1_Data!M9 -> 0.8 | C6: =$I$5 -> 0.36190476 | D6: =$I$7 -> 1 | E6: =$I$8 -> 0 | F6: =IF(OR(B6>$I$7,B6<$I$8),B6,NA()) -> #N/A | G6: =IF(AND(B6<=$I$7,B6>=$I$8),1,0) -> 1 | H6: SE | I6: =SQRT(I5*(1-I5)/I4) -> 0.21490915 | K6: LCL 2s | L6: =MAX(0,$L$2-2*SQRT($I$4*$I$5*(1-$I$5))) -> 0
A7: =P1_Data!A10 -> 4 | B7: =P1_Data!M10 -> 0.4 | C7: =$I$5 -> 0.36190476 | D7: =$I$7 -> 1 | E7: =$I$8 -> 0 | F7: =IF(OR(B7>$I$7,B7<$I$8),B7,NA()) -> #N/A | G7: =IF(AND(B7<=$I$7,B7>=$I$8),1,0) -> 1 | H7: UCL 3s | I7: =MIN(1,I5+3*I6) -> 1
A8: =P1_Data!A11 -> 5 | B8: =P1_Data!M11 -> 0.6 | C8: =$I$5 -> 0.36190476 | D8: =$I$7 -> 1 | E8: =$I$8 -> 0 | F8: =IF(OR(B8>$I$7,B8<$I$8),B8,NA()) -> #N/A | G8: =IF(AND(B8<=$I$7,B8>=$I$8),1,0) -> 1 | H8: LCL 3s | I8: =MAX(0,I5-3*I6) -> 0 | K8: Sample | L8: np_i | M8: npCL | N8: npUCL3 | O8: npLCL3
A9: =P1_Data!A12 -> 6 | B9: =P1_Data!M12 -> 0.4 | C9: =$I$5 -> 0.36190476 | D9: =$I$7 -> 1 | E9: =$I$8 -> 0 | F9: =IF(OR(B9>$I$7,B9<$I$8),B9,NA()) -> #N/A | G9: =IF(AND(B9<=$I$7,B9>=$I$8),1,0) -> 1 | H9: UCL 2s | I9: =MIN(1,I5+2*I6) -> 0.79172305 | K9: =P1_Data!A7 -> 1 | L9: =P1_Data!N7 -> 3 | M9: =$L$2 -> 1.8095238 | N9: =$L$3 -> 5.033161 | O9: =$L$4 -> 0
A10: =P1_Data!A13 -> 7 | B10: =P1_Data!M13 -> 0.8 | C10: =$I$5 -> 0.36190476 | D10: =$I$7 -> 1 | E10: =$I$8 -> 0 | F10: =IF(OR(B10>$I$7,B10<$I$8),B10,NA()) -> #N/A | G10: =IF(AND(B10<=$I$7,B10>=$I$8),1,0) -> 1 | H10: LCL 2s | I10: =MAX(0,I5-2*I6) -> 0 | K10: =P1_Data!A8 -> 2 | L10: =P1_Data!N8 -> 0 | M10: =$L$2 -> 1.8095238 | N10: =$L$3 -> 5.033161 | O10: =$L$4 -> 0
A11: =P1_Data!A14 -> 8 | B11: =P1_Data!M14 -> 0.6 | C11: =$I$5 -> 0.36190476 | D11: =$I$7 -> 1 | E11: =$I$8 -> 0 | F11: =IF(OR(B11>$I$7,B11<$I$8),B11,NA()) -> #N/A | G11: =IF(AND(B11<=$I$7,B11>=$I$8),1,0) -> 1 | H11: UCL 1s | I11: =MIN(1,I5+I6) -> 0.57681391 | K11: =P1_Data!A9 -> 3 | L11: =P1_Data!N9 -> 4 | M11: =$L$2 -> 1.8095238 | N11: =$L$3 -> 5.033161 | O11: =$L$4 -> 0
A12: =P1_Data!A15 -> 9 | B12: =P1_Data!M15 -> 0.6 | C12: =$I$5 -> 0.36190476 | D12: =$I$7 -> 1 | E12: =$I$8 -> 0 | F12: =IF(OR(B12>$I$7,B12<$I$8),B12,NA()) -> #N/A | G12: =IF(AND(B12<=$I$7,B12>=$I$8),1,0) -> 1 | H12: LCL 1s | I12: =MAX(0,I5-I6) -> 0.14699562 | K12: =P1_Data!A10 -> 4 | L12: =P1_Data!N10 -> 2 | M12: =$L$2 -> 1.8095238 | N12: =$L$3 -> 5.033161 | O12: =$L$4 -> 0
A13: =P1_Data!A16 -> 10 | B13: =P1_Data!M16 -> 0.2 | C13: =$I$5 -> 0.36190476 | D13: =$I$7 -> 1 | E13: =$I$8 -> 0 | F13: =IF(OR(B13>$I$7,B13<$I$8),B13,NA()) -> #N/A | G13: =IF(AND(B13<=$I$7,B13>=$I$8),1,0) -> 1 | K13: =P1_Data!A11 -> 5 | L13: =P1_Data!N11 -> 3 | M13: =$L$2 -> 1.8095238 | N13: =$L$3 -> 5.033161 | O13: =$L$4 -> 0
A14: =P1_Data!A17 -> 11 | B14: =P1_Data!M17 -> 0.4 | C14: =$I$5 -> 0.36190476 | D14: =$I$7 -> 1 | E14: =$I$8 -> 0 | F14: =IF(OR(B14>$I$7,B14<$I$8),B14,NA()) -> #N/A | G14: =IF(AND(B14<=$I$7,B14>=$I$8),1,0) -> 1 | H14: ROUND 2 PARAMETERS (OOC points excluded) | K14: =P1_Data!A12 -> 6 | L14: =P1_Data!N12 -> 2 | M14: =$L$2 -> 1.8095238 | N14: =$L$3 -> 5.033161 | O14: =$L$4 -> 0
A15: =P1_Data!A18 -> 12 | B15: =P1_Data!M18 -> 0.2 | C15: =$I$5 -> 0.36190476 | D15: =$I$7 -> 1 | E15: =$I$8 -> 0 | F15: =IF(OR(B15>$I$7,B15<$I$8),B15,NA()) -> #N/A | G15: =IF(AND(B15<=$I$7,B15>=$I$8),1,0) -> 1 | H15: Rule: exclude samples with p_i outside Round-1 3σ limits, then recompute. | K15: =P1_Data!A13 -> 7 | L15: =P1_Data!N13 -> 4 | M15: =$L$2 -> 1.8095238 | N15: =$L$3 -> 5.033161 | O15: =$L$4 -> 0
A16: =P1_Data!A19 -> 13 | B16: =P1_Data!M19 -> 0.6 | C16: =$I$5 -> 0.36190476 | D16: =$I$7 -> 1 | E16: =$I$8 -> 0 | F16: =IF(OR(B16>$I$7,B16<$I$8),B16,NA()) -> #N/A | G16: =IF(AND(B16<=$I$7,B16>=$I$8),1,0) -> 1 | K16: =P1_Data!A14 -> 8 | L16: =P1_Data!N14 -> 3 | M16: =$L$2 -> 1.8095238 | N16: =$L$3 -> 5.033161 | O16: =$L$4 -> 0
A17: =P1_Data!A20 -> 14 | B17: =P1_Data!M20 -> 0.8 | C17: =$I$5 -> 0.36190476 | D17: =$I$7 -> 1 | E17: =$I$8 -> 0 | F17: =IF(OR(B17>$I$7,B17<$I$8),B17,NA()) -> #N/A | G17: =IF(AND(B17<=$I$7,B17>=$I$8),1,0) -> 1 | H17: Defects (incl.) | I17: =SUMPRODUCT(P1_Data!K7:K48,G4:G45) -> 76 | K17: =P1_Data!A15 -> 9 | L17: =P1_Data!N15 -> 3 | M17: =$L$2 -> 1.8095238 | N17: =$L$3 -> 5.033161 | O17: =$L$4 -> 0
A18: =P1_Data!A21 -> 15 | B18: =P1_Data!M21 -> 0.8 | C18: =$I$5 -> 0.36190476 | D18: =$I$7 -> 1 | E18: =$I$8 -> 0 | F18: =IF(OR(B18>$I$7,B18<$I$8),B18,NA()) -> #N/A | G18: =IF(AND(B18<=$I$7,B18>=$I$8),1,0) -> 1 | H18: Pieces (incl.) | I18: =SUMPRODUCT(P1_Data!J7:J48,G4:G45) -> 210 | K18: =P1_Data!A16 -> 10 | L18: =P1_Data!N16 -> 1 | M18: =$L$2 -> 1.8095238 | N18: =$L$3 -> 5.033161 | O18: =$L$4 -> 0
A19: =P1_Data!A22 -> 16 | B19: =P1_Data!M22 -> 0.6 | C19: =$I$5 -> 0.36190476 | D19: =$I$7 -> 1 | E19: =$I$8 -> 0 | F19: =IF(OR(B19>$I$7,B19<$I$8),B19,NA()) -> #N/A | G19: =IF(AND(B19<=$I$7,B19>=$I$8),1,0) -> 1 | H19: p_bar R2 | I19: =I17/I18 -> 0.36190476 | K19: =P1_Data!A17 -> 11 | L19: =P1_Data!N17 -> 2 | M19: =$L$2 -> 1.8095238 | N19: =$L$3 -> 5.033161 | O19: =$L$4 -> 0
A20: =P1_Data!A23 -> 17 | B20: =P1_Data!M23 -> 0.6 | C20: =$I$5 -> 0.36190476 | D20: =$I$7 -> 1 | E20: =$I$8 -> 0 | F20: =IF(OR(B20>$I$7,B20<$I$8),B20,NA()) -> #N/A | G20: =IF(AND(B20<=$I$7,B20>=$I$8),1,0) -> 1 | H20: SE R2 | I20: =SQRT(I19*(1-I19)/$I$4) -> 0.21490915 | K20: =P1_Data!A18 -> 12 | L20: =P1_Data!N18 -> 1 | M20: =$L$2 -> 1.8095238 | N20: =$L$3 -> 5.033161 | O20: =$L$4 -> 0
A21: =P1_Data!A24 -> 18 | B21: =P1_Data!M24 -> 0.6 | C21: =$I$5 -> 0.36190476 | D21: =$I$7 -> 1 | E21: =$I$8 -> 0 | F21: =IF(OR(B21>$I$7,B21<$I$8),B21,NA()) -> #N/A | G21: =IF(AND(B21<=$I$7,B21>=$I$8),1,0) -> 1 | H21: UCL 3s R2 | I21: =MIN(1,I19+3*I20) -> 1 | K21: =P1_Data!A19 -> 13 | L21: =P1_Data!N19 -> 3 | M21: =$L$2 -> 1.8095238 | N21: =$L$3 -> 5.033161 | O21: =$L$4 -> 0
A22: =P1_Data!A25 -> 19 | B22: =P1_Data!M25 -> 0 | C22: =$I$5 -> 0.36190476 | D22: =$I$7 -> 1 | E22: =$I$8 -> 0 | F22: =IF(OR(B22>$I$7,B22<$I$8),B22,NA()) -> #N/A | G22: =IF(AND(B22<=$I$7,B22>=$I$8),1,0) -> 1 | H22: LCL 3s R2 | I22: =MAX(0,I19-3*I20) -> 0 | K22: =P1_Data!A20 -> 14 | L22: =P1_Data!N20 -> 4 | M22: =$L$2 -> 1.8095238 | N22: =$L$3 -> 5.033161 | O22: =$L$4 -> 0
A23: =P1_Data!A26 -> 20 | B23: =P1_Data!M26 -> 0 | C23: =$I$5 -> 0.36190476 | D23: =$I$7 -> 1 | E23: =$I$8 -> 0 | F23: =IF(OR(B23>$I$7,B23<$I$8),B23,NA()) -> #N/A | G23: =IF(AND(B23<=$I$7,B23>=$I$8),1,0) -> 1 | K23: =P1_Data!A21 -> 15 | L23: =P1_Data!N21 -> 4 | M23: =$L$2 -> 1.8095238 | N23: =$L$3 -> 5.033161 | O23: =$L$4 -> 0
A24: =P1_Data!A27 -> 21 | B24: =P1_Data!M27 -> 0 | C24: =$I$5 -> 0.36190476 | D24: =$I$7 -> 1 | E24: =$I$8 -> 0 | F24: =IF(OR(B24>$I$7,B24<$I$8),B24,NA()) -> #N/A | G24: =IF(AND(B24<=$I$7,B24>=$I$8),1,0) -> 1 | K24: =P1_Data!A22 -> 16 | L24: =P1_Data!N22 -> 3 | M24: =$L$2 -> 1.8095238 | N24: =$L$3 -> 5.033161 | O24: =$L$4 -> 0
A25: =P1_Data!A7 -> 1 | B25: =P1_Data!M7 -> 0.6 | C25: =$I$19 -> 0.36190476 | D25: =$I$21 -> 1 | E25: =$I$22 -> 0 | F25: =IF(OR(B25>$I$21,B25<$I$22),B25,NA()) -> #N/A | G25: =IF(AND(B25<=$I$7,B25>=$I$8),1,0) -> 1 | K25: =P1_Data!A23 -> 17 | L25: =P1_Data!N23 -> 3 | M25: =$L$2 -> 1.8095238 | N25: =$L$3 -> 5.033161 | O25: =$L$4 -> 0
A26: =P1_Data!A8 -> 2 | B26: =P1_Data!M8 -> 0 | C26: =$I$19 -> 0.36190476 | D26: =$I$21 -> 1 | E26: =$I$22 -> 0 | F26: =IF(OR(B26>$I$21,B26<$I$22),B26,NA()) -> #N/A | G26: =IF(AND(B26<=$I$7,B26>=$I$8),1,0) -> 1 | K26: =P1_Data!A24 -> 18 | L26: =P1_Data!N24 -> 3 | M26: =$L$2 -> 1.8095238 | N26: =$L$3 -> 5.033161 | O26: =$L$4 -> 0
A27: =P1_Data!A9 -> 3 | B27: =P1_Data!M9 -> 0.8 | C27: =$I$19 -> 0.36190476 | D27: =$I$21 -> 1 | E27: =$I$22 -> 0 | F27: =IF(OR(B27>$I$21,B27<$I$22),B27,NA()) -> #N/A | G27: =IF(AND(B27<=$I$7,B27>=$I$8),1,0) -> 1 | K27: =P1_Data!A25 -> 19 | L27: =P1_Data!N25 -> 0 | M27: =$L$2 -> 1.8095238 | N27: =$L$3 -> 5.033161 | O27: =$L$4 -> 0
A28: =P1_Data!A10 -> 4 | B28: =P1_Data!M10 -> 0.4 | C28: =$I$19 -> 0.36190476 | D28: =$I$21 -> 1 | E28: =$I$22 -> 0 | F28: =IF(OR(B28>$I$21,B28<$I$22),B28,NA()) -> #N/A | G28: =IF(AND(B28<=$I$7,B28>=$I$8),1,0) -> 1 | K28: =P1_Data!A26 -> 20 | L28: =P1_Data!N26 -> 0 | M28: =$L$2 -> 1.8095238 | N28: =$L$3 -> 5.033161 | O28: =$L$4 -> 0
A29: =P1_Data!A11 -> 5 | B29: =P1_Data!M11 -> 0.6 | C29: =$I$19 -> 0.36190476 | D29: =$I$21 -> 1 | E29: =$I$22 -> 0 | F29: =IF(OR(B29>$I$21,B29<$I$22),B29,NA()) -> #N/A | G29: =IF(AND(B29<=$I$7,B29>=$I$8),1,0) -> 1 | K29: =P1_Data!A27 -> 21 | L29: =P1_Data!N27 -> 0 | M29: =$L$2 -> 1.8095238 | N29: =$L$3 -> 5.033161 | O29: =$L$4 -> 0
A30: =P1_Data!A12 -> 6 | B30: =P1_Data!M12 -> 0.4 | C30: =$I$19 -> 0.36190476 | D30: =$I$21 -> 1 | E30: =$I$22 -> 0 | F30: =IF(OR(B30>$I$21,B30<$I$22),B30,NA()) -> #N/A | G30: =IF(AND(B30<=$I$7,B30>=$I$8),1,0) -> 1 | K30: =P1_Data!A28 -> 22 | L30: =P1_Data!N28 -> 0 | M30: =$L$2 -> 1.8095238 | N30: =$L$3 -> 5.033161 | O30: =$L$4 -> 0
A31: =P1_Data!A13 -> 7 | B31: =P1_Data!M13 -> 0.8 | C31: =$I$19 -> 0.36190476 | D31: =$I$21 -> 1 | E31: =$I$22 -> 0 | F31: =IF(OR(B31>$I$21,B31<$I$22),B31,NA()) -> #N/A | G31: =IF(AND(B31<=$I$7,B31>=$I$8),1,0) -> 1 | K31: =P1_Data!A29 -> 23 | L31: =P1_Data!N29 -> 0 | M31: =$L$2 -> 1.8095238 | N31: =$L$3 -> 5.033161 | O31: =$L$4 -> 0
A32: =P1_Data!A14 -> 8 | B32: =P1_Data!M14 -> 0.6 | C32: =$I$19 -> 0.36190476 | D32: =$I$21 -> 1 | E32: =$I$22 -> 0 | F32: =IF(OR(B32>$I$21,B32<$I$22),B32,NA()) -> #N/A | G32: =IF(AND(B32<=$I$7,B32>=$I$8),1,0) -> 1 | K32: =P1_Data!A30 -> 24 | L32: =P1_Data!N30 -> 0 | M32: =$L$2 -> 1.8095238 | N32: =$L$3 -> 5.033161 | O32: =$L$4 -> 0
A33: =P1_Data!A15 -> 9 | B33: =P1_Data!M15 -> 0.6 | C33: =$I$19 -> 0.36190476 | D33: =$I$21 -> 1 | E33: =$I$22 -> 0 | F33: =IF(OR(B33>$I$21,B33<$I$22),B33,NA()) -> #N/A | G33: =IF(AND(B33<=$I$7,B33>=$I$8),1,0) -> 1 | K33: =P1_Data!A31 -> 25 | L33: =P1_Data!N31 -> 3 | M33: =$L$2 -> 1.8095238 | N33: =$L$3 -> 5.033161 | O33: =$L$4 -> 0
A34: =P1_Data!A16 -> 10 | B34: =P1_Data!M16 -> 0.2 | C34: =$I$19 -> 0.36190476 | D34: =$I$21 -> 1 | E34: =$I$22 -> 0 | F34: =IF(OR(B34>$I$21,B34<$I$22),B34,NA()) -> #N/A | G34: =IF(AND(B34<=$I$7,B34>=$I$8),1,0) -> 1 | K34: =P1_Data!A32 -> 26 | L34: =P1_Data!N32 -> 2 | M34: =$L$2 -> 1.8095238 | N34: =$L$3 -> 5.033161 | O34: =$L$4 -> 0
A35: =P1_Data!A17 -> 11 | B35: =P1_Data!M17 -> 0.4 | C35: =$I$19 -> 0.36190476 | D35: =$I$21 -> 1 | E35: =$I$22 -> 0 | F35: =IF(OR(B35>$I$21,B35<$I$22),B35,NA()) -> #N/A | G35: =IF(AND(B35<=$I$7,B35>=$I$8),1,0) -> 1 | K35: =P1_Data!A33 -> 27 | L35: =P1_Data!N33 -> 2 | M35: =$L$2 -> 1.8095238 | N35: =$L$3 -> 5.033161 | O35: =$L$4 -> 0
A36: =P1_Data!A18 -> 12 | B36: =P1_Data!M18 -> 0.2 | C36: =$I$19 -> 0.36190476 | D36: =$I$21 -> 1 | E36: =$I$22 -> 0 | F36: =IF(OR(B36>$I$21,B36<$I$22),B36,NA()) -> #N/A | G36: =IF(AND(B36<=$I$7,B36>=$I$8),1,0) -> 1 | K36: =P1_Data!A34 -> 28 | L36: =P1_Data!N34 -> 3 | M36: =$L$2 -> 1.8095238 | N36: =$L$3 -> 5.033161 | O36: =$L$4 -> 0
... A38: =P1_Data!A20 -> 14 | B38: =P1_Data!M20 -> 0.8 | C38: =$I$19 -> 0.36190476 | D38: =$I$21 -> 1 | E38: =$I$22 -> 0 | F38: =IF(OR(B38>$I$21,B38<$I$22),B38,NA()) -> #N/A | G38: =IF(AND(B38<=$I$7,B38>=$I$8),1,0) -> 1 | K38: =P1_Data!A36 -> 30 | L38: =P1_Data!N36 -> 2 | M38: =$L$2 -> 1.8095238 | N38: =$L$3 -> 5.033161 | O38: =$L$4 -> 0
A39: =P1_Data!A21 -> 15 | B39: =P1_Data!M21 -> 0.8 | C39: =$I$19 -> 0.36190476 | D39: =$I$21 -> 1 | E39: =$I$22 -> 0 | F39: =IF(OR(B39>$I$21,B39<$I$22),B39,NA()) -> #N/A | G39: =IF(AND(B39<=$I$7,B39>=$I$8),1,0) -> 1 | K39: White | L39: =SUMIF(P1_Data!$G$7:$G$48,K39,P1_Data!$K$7:$K$48) -> 20 | M39: =SUM($L$39:L39)/SUM($L$39:$L$45) -> 0.26315789 | N39: =$L$3 -> 5.033161 | O39: =$L$4 -> 0
A40: =P1_Data!A22 -> 16 | B40: =P1_Data!M22 -> 0.6 | C40: =$I$19 -> 0.36190476 | D40: =$I$21 -> 1 | E40: =$I$22 -> 0 | F40: =IF(OR(B40>$I$21,B40<$I$22),B40,NA()) -> #N/A | G40: =IF(AND(B40<=$I$7,B40>=$I$8),1,0) -> 1 | K40: Dark Blue | L40: =SUMIF(P1_Data!$G$7:$G$48,K40,P1_Data!$K$7:$K$48) -> 15 | M40: =SUM($L$39:L40)/SUM($L$39:$L$45) -> 0.46052632 | N40: =$L$3 -> 5.033161 | O40: =$L$4 -> 0
A41: =P1_Data!A23 -> 17 | B41: =P1_Data!M23 -> 0.6 | C41: =$I$19 -> 0.36190476 | D41: =$I$21 -> 1 | E41: =$I$22 -> 0 | F41: =IF(OR(B41>$I$21,B41<$I$22),B41,NA()) -> #N/A | G41: =IF(AND(B41<=$I$7,B41>=$I$8),1,0) -> 1 | K41: Yellow | L41: =SUMIF(P1_Data!$G$7:$G$48,K41,P1_Data!$K$7:$K$48) -> 14 | M41: =SUM($L$39:L41)/SUM($L$39:$L$45) -> 0.64473684 | N41: =$L$3 -> 5.033161 | O41: =$L$4 -> 0
...

Sheet P2_Data
A1: Process 2 — Assembly Run Data (colour-binned feed; first defect discards whole semi-assembly)
A2: Provenance: Pieces_Before_Defect_g, Defect_Found, Opportunity = Raw observed. Defect_Colour per run = Reconstructed (aggregate colour totals preserved: Orange 10 / Red 10 / Yellow 4 / Dark Blue 4). Time_Band/Pick_Order/Colour_Sequence/Assignable_Cause = Reconstructed classification. g=acceptable pieces before defect (higher=better). u_i=Defect/Opportunity.
A6: Run_ID | B6: Data_Source_Type | C6: Phase | D6: Time_Band | E6: Pick_Order | F6: Colour_Sequence | G6: Defect_Colour | H6: Pieces_Before_Defect_g | I6: Pieces_Placed_Including_Defect | J6: Defect_Found_1_0 | K6: Assembly_Discarded_1_0 | L6: Completed_Assembly_1_0 | M6: Opportunity_Count | N6: u_i | O6: Assignable_Cause_Flag | P6: Assignable_Cause_Category | Q6: Assignable_Cause_Description | R6: Operator_Comment | S6: Analysis_Use
A7: 1 | B7: Raw observed (colour: Reconstructed) | C7: Phase 1 | D7: Early | E7: 4+1 | F7: Mixed→Red | G7: Red | H7: 4 | I7: =H7+J7 -> 5 | J7: 1 | K7: 1 | L7: 0 | M7: =I7 -> 5 | N7: =J7/M7 -> 0.2 | O7: 0 | P7: None | Q7: Defect encountered mid-assembly | R7: Routine discard | S7: g-chart + u-chart + Pareto
A8: 2 | B8: Raw observed (colour: Reconstructed) | C8: Phase 1 | D8: Early | E8: 3+1 | F8: Mixed→Orange | G8: Orange | H8: 3 | I8: =H8+J8 -> 4 | J8: 1 | K8: 1 | L8: 0 | M8: =I8 -> 4 | N8: =J8/M8 -> 0.25 | O8: 1 | P8: High-defect colour reached early | Q8: Orange (high-defect colour) picked at position 4, early discard | R8: Early high-defect-colour discard | S8: g-chart + u-chart + Pareto
A9: 3 | B9: Raw observed (colour: Reconstructed) | C9: Phase 1 | D9: Early | E9: 3+1 | F9: Mixed→Orange | G9: Orange | H9: 3 | I9: =H9+J9 -> 4 | J9: 1 | K9: 1 | L9: 0 | M9: =I9 -> 4 | N9: =J9/M9 -> 0.25 | O9: 1 | P9: High-defect colour reached early | Q9: Orange (high-defect colour) picked at position 4, early discard | R9: Early high-defect-colour discard | S9: g-chart + u-chart + Pareto
A10: 4 | B10: Raw observed (colour: Reconstructed) | C10: Phase 1 | D10: Early | E10: 3+1 | F10: Mixed→Orange | G10: Orange | H10: 3 | I10: =H10+J10 -> 4 | J10: 1 | K10: 1 | L10: 0 | M10: =I10 -> 4 | N10: =J10/M10 -> 0.25 | O10: 1 | P10: High-defect colour reached early | Q10: Orange (high-defect colour) picked at position 4, early discard | R10: Early high-defect-colour discard | S10: g-chart + u-chart + Pareto
A11: 5 | B11: Raw observed (colour: Reconstructed) | C11: Phase 1 | D11: Early | E11: 4+1 | F11: Mixed→Red | G11: Red | H11: 4 | I11: =H11+J11 -> 5 | J11: 1 | K11: 1 | L11: 0 | M11: =I11 -> 5 | N11: =J11/M11 -> 0.2 | O11: 0 | P11: None | Q11: Defect encountered mid-assembly | R11: Routine discard | S11: g-chart + u-chart + Pareto
A12: 6 | B12: Raw observed (colour: Reconstructed) | C12: Phase 1 | D12: Early | E12: 3+1 | F12: Mixed→Orange | G12: Orange | H12: 3 | I12: =H12+J12 -> 4 | J12: 1 | K12: 1 | L12: 0 | M12: =I12 -> 4 | N12: =J12/M12 -> 0.25 | O12: 1 | P12: High-defect colour reached early | Q12: Orange (high-defect colour) picked at position 4, early discard | R12: Early high-defect-colour discard | S12: g-chart + u-chart + Pareto
A13: 7 | B13: Raw observed (colour: Reconstructed) | C13: Phase 1 | D13: Early | E13: 6+1 | F13: Mixed→Dark Blue | G13: Dark Blue | H13: 6 | I13: =H13+J13 -> 7 | J13: 1 | K13: 1 | L13: 0 | M13: =I13 -> 7 | N13: =J13/M13 -> 0.14285714 | O13: 0 | P13: None | Q13: Defect encountered mid-assembly | R13: Routine discard | S13: g-chart + u-chart + Pareto
A14: 8 | B14: Raw observed (colour: Reconstructed) | C14: Phase 1 | D14: Early | E14: 5+1 | F14: Mixed→Yellow | G14: Yellow | H14: 5 | I14: =H14+J14 -> 6 | J14: 1 | K14: 1 | L14: 0 | M14: =I14 -> 6 | N14: =J14/M14 -> 0.16666667 | O14: 0 | P14: None | Q14: Defect encountered mid-assembly | R14: Routine discard | S14: g-chart + u-chart + Pareto
A15: 9 | B15: Raw observed (colour: Reconstructed) | C15: Phase 1 | D15: Early | E15: 4+1 | F15: Mixed→Red | G15: Red | H15: 4 | I15: =H15+J15 -> 5 | J15: 1 | K15: 1 | L15: 0 | M15: =I15 -> 5 | N15: =J15/M15 -> 0.2 | O15: 0 | P15: None | Q15: Defect encountered mid-assembly | R15: Routine discard | S15: g-chart + u-chart + Pareto
A16: 10 | B16: Raw observed (colour: Reconstructed) | C16: Phase 1 | D16: Early | E16: 4+1 | F16: Mixed→Red | G16: Red | H16: 4 | I16: =H16+J16 -> 5 | J16: 1 | K16: 1 | L16: 0 | M16: =I16 -> 5 | N16: =J16/M16 -> 0.2 | O16: 0 | P16: None | Q16: Defect encountered mid-assembly | R16: Routine discard | S16: g-chart + u-chart + Pareto
A17: 11 | B17: Raw observed (colour: Reconstructed) | C17: Phase 1 | D17: Middle | E17: 5+1 | F17: Mixed→Yellow | G17: Yellow | H17: 5 | I17: =H17+J17 -> 6 | J17: 1 | K17: 1 | L17: 0 | M17: =I17 -> 6 | N17: =J17/M17 -> 0.16666667 | O17: 0 | P17: None | Q17: Defect encountered mid-assembly | R17: Routine discard | S17: g-chart + u-chart + Pareto
A18: 12 | B18: Raw observed (colour: Reconstructed) | C18: Phase 1 | D18: Middle | E18: 3+1 | F18: Mixed→Orange | G18: Orange | H18: 3 | I18: =H18+J18 -> 4 | J18: 1 | K18: 1 | L18: 0 | M18: =I18 -> 4 | N18: =J18/M18 -> 0.25 | O18: 1 | P18: High-defect colour reached early | Q18: Orange (high-defect colour) picked at position 4, early discard | R18: Early high-defect-colour discard | S18: g-chart + u-chart + Pareto
... A36: 30 | B36: Raw observed (colour: Reconstructed) | C36: Phase 1 | D36: Late | E36: 4+1 | F36: Mixed→Red | G36: Red | H36: 4 | I36: =H36+J36 -> 5 | J36: 1 | K36: 1 | L36: 0 | M36: =I36 -> 5 | N36: =J36/M36 -> 0.2 | O36: 0 | P36: None | Q36: Defect encountered mid-assembly | R36: Routine discard | S36: g-chart + u-chart + Pareto
A37: TOTAL | J37: =SUM(J7:J36) -> 30 | M37: =SUM(M7:M36) -> 151
A39: Legend: | B39: Raw observed | D39: Reconstructed classification

Sheet P2_Analysis
A1: Process 2 — u-chart + g-chart + Pareto | H1: PARAMETERS
H2: Total defects | I2: =SUM(P2_Data!J7:J36) -> 30
H3: Total opportunities | I3: =SUM(P2_Data!M7:M36) -> 151
H4: u_bar | I4: =I2/I3 -> 0.1986755
H5: g_bar | I5: =AVERAGE(P2_Data!H7:H36) -> 4.0333333
H6: p_hat=1/(g_bar+1) | I6: =1/(I5+1) -> 0.1986755
A8: Run | B8: u_i | C8: u_bar | D8: UCL_3σ | E8: LCL_3σ
A9: =P2_Data!A7 -> 1 | B9: =P2_Data!N7 -> 0.2 | C9: =$I$4 -> 0.1986755 | D9: =$I$4+3*SQRT($I$4/P2_Data!M7) -> 0.79668544 | E9: =MAX(0,$I$4-3*SQRT($I$4/P2_Data!M7)) -> 0
A10: =P2_Data!A8 -> 2 | B10: =P2_Data!N8 -> 0.25 | C10: =$I$4 -> 0.1986755 | D10: =$I$4+3*SQRT($I$4/P2_Data!M8) -> 0.86727094 | E10: =MAX(0,$I$4-3*SQRT($I$4/P2_Data!M8)) -> 0 | H10: g-chart (geometric approx., higher = better)
A11: =P2_Data!A9 -> 3 | B11: =P2_Data!N9 -> 0.25 | C11: =$I$4 -> 0.1986755 | D11: =$I$4+3*SQRT($I$4/P2_Data!M9) -> 0.86727094 | E11: =MAX(0,$I$4-3*SQRT($I$4/P2_Data!M9)) -> 0 | H11: Run | I11: g_i | J11: g_bar | K11: UCL_3σ | L11: LCL_3σ
A12: =P2_Data!A10 -> 4 | B12: =P2_Data!N10 -> 0.25 | C12: =$I$4 -> 0.1986755 | D12: =$I$4+3*SQRT($I$4/P2_Data!M10) -> 0.86727094 | E12: =MAX(0,$I$4-3*SQRT($I$4/P2_Data!M10)) -> 0 | H12: =P2_Data!A7 -> 1 | I12: =P2_Data!H7 -> 4 | J12: =$I$5 -> 4.0333333 | K12: =MIN(7,$I$5+3*SQRT((1-$I$6)/$I$6^2)) -> 7 | L12: =MAX(0,$I$5-3*SQRT((1-$I$6)/$I$6^2)) -> 0
A13: =P2_Data!A11 -> 5 | B13: =P2_Data!N11 -> 0.2 | C13: =$I$4 -> 0.1986755 | D13: =$I$4+3*SQRT($I$4/P2_Data!M11) -> 0.79668544 | E13: =MAX(0,$I$4-3*SQRT($I$4/P2_Data!M11)) -> 0 | H13: =P2_Data!A8 -> 2 | I13: =P2_Data!H8 -> 3 | J13: =$I$5 -> 4.0333333 | K13: =MIN(7,$I$5+3*SQRT((1-$I$6)/$I$6^2)) -> 7 | L13: =MAX(0,$I$5-3*SQRT((1-$I$6)/$I$6^2)) -> 0
A14: =P2_Data!A12 -> 6 | B14: =P2_Data!N12 -> 0.25 | C14: =$I$4 -> 0.1986755 | D14: =$I$4+3*SQRT($I$4/P2_Data!M12) -> 0.86727094 | E14: =MAX(0,$I$4-3*SQRT($I$4/P2_Data!M12)) -> 0 | H14: =P2_Data!A9 -> 3 | I14: =P2_Data!H9 -> 3 | J14: =$I$5 -> 4.0333333 | K14: =MIN(7,$I$5+3*SQRT((1-$I$6)/$I$6^2)) -> 7 | L14: =MAX(0,$I$5-3*SQRT((1-$I$6)/$I$6^2)) -> 0
A15: =P2_Data!A13 -> 7 | B15: =P2_Data!N13 -> 0.14285714 | C15: =$I$4 -> 0.1986755 | D15: =$I$4+3*SQRT($I$4/P2_Data!M13) -> 0.70408615 | E15: =MAX(0,$I$4-3*SQRT($I$4/P2_Data!M13)) -> 0 | H15: =P2_Data!A10 -> 4 | I15: =P2_Data!H10 -> 3 | J15: =$I$5 -> 4.0333333 | K15: =MIN(7,$I$5+3*SQRT((1-$I$6)/$I$6^2)) -> 7 | L15: =MAX(0,$I$5-3*SQRT((1-$I$6)/$I$6^2)) -> 0
A16: =P2_Data!A14 -> 8 | B16: =P2_Data!N14 -> 0.16666667 | C16: =$I$4 -> 0.1986755 | D16: =$I$4+3*SQRT($I$4/P2_Data!M14) -> 0.74458139 | E16: =MAX(0,$I$4-3*SQRT($I$4/P2_Data!M14)) -> 0 | H16: =P2_Data!A11 -> 5 | I16: =P2_Data!H11 -> 4 | J16: =$I$5 -> 4.0333333 | K16: =MIN(7,$I$5+3*SQRT((1-$I$6)/$I$6^2)) -> 7 | L16: =MAX(0,$I$5-3*SQRT((1-$I$6)/$I$6^2)) -> 0
A17: =P2_Data!A15 -> 9 | B17: =P2_Data!N15 -> 0.2 | C17: =$I$4 -> 0.1986755 | D17: =$I$4+3*SQRT($I$4/P2_Data!M15) -> 0.79668544 | E17: =MAX(0,$I$4-3*SQRT($I$4/P2_Data!M15)) -> 0 | H17: =P2_Data!A12 -> 6 | I17: =P2_Data!H12 -> 3 | J17: =$I$5 -> 4.0333333 | K17: =MIN(7,$I$5+3*SQRT((1-$I$6)/$I$6^2)) -> 7 | L17: =MAX(0,$I$5-3*SQRT((1-$I$6)/$I$6^2)) -> 0
A18: =P2_Data!A16 -> 10 | B18: =P2_Data!N16 -> 0.2 | C18: =$I$4 -> 0.1986755 | D18: =$I$4+3*SQRT($I$4/P2_Data!M16) -> 0.79668544 | E18: =MAX(0,$I$4-3*SQRT($I$4/P2_Data!M16)) -> 0 | H18: =P2_Data!A13 -> 7 | I18: =P2_Data!H13 -> 6 | J18: =$I$5 -> 4.0333333 | K18: =MIN(7,$I$5+3*SQRT((1-$I$6)/$I$6^2)) -> 7 | L18: =MAX(0,$I$5-3*SQRT((1-$I$6)/$I$6^2)) -> 0
A19: =P2_Data!A17 -> 11 | B19: =P2_Data!N17 -> 0.16666667 | C19: =$I$4 -> 0.1986755 | D19: =$I$4+3*SQRT($I$4/P2_Data!M17) -> 0.74458139 | E19: =MAX(0,$I$4-3*SQRT($I$4/P2_Data!M17)) -> 0 | H19: =P2_Data!A14 -> 8 | I19: =P2_Data!H14 -> 5 | J19: =$I$5 -> 4.0333333 | K19: =MIN(7,$I$5+3*SQRT((1-$I$6)/$I$6^2)) -> 7 | L19: =MAX(0,$I$5-3*SQRT((1-$I$6)/$I$6^2)) -> 0
A20: =P2_Data!A18 -> 12 | B20: =P2_Data!N18 -> 0.25 | C20: =$I$4 -> 0.1986755 | D20: =$I$4+3*SQRT($I$4/P2_Data!M18) -> 0.86727094 | E20: =MAX(0,$I$4-3*SQRT($I$4/P2_Data!M18)) -> 0 | H20: =P2_Data!A15 -> 9 | I20: =P2_Data!H15 -> 4 | J20: =$I$5 -> 4.0333333 | K20: =MIN(7,$I$5+3*SQRT((1-$I$6)/$I$6^2)) -> 7 | L20: =MAX(0,$I$5-3*SQRT((1-$I$6)/$I$6^2)) -> 0
A21: =P2_Data!A19 -> 13 | B21: =P2_Data!N19 -> 0.14285714 | C21: =$I$4 -> 0.1986755 | D21: =$I$4+3*SQRT($I$4/P2_Data!M19) -> 0.70408615 | E21: =MAX(0,$I$4-3*SQRT($I$4/P2_Data!M19)) -> 0 | H21: =P2_Data!A16 -> 10 | I21: =P2_Data!H16 -> 4 | J21: =$I$5 -> 4.0333333 | K21: =MIN(7,$I$5+3*SQRT((1-$I$6)/$I$6^2)) -> 7 | L21: =MAX(0,$I$5-3*SQRT((1-$I$6)/$I$6^2)) -> 0
A22: =P2_Data!A20 -> 14 | B22: =P2_Data!N20 -> 0.16666667 | C22: =$I$4 -> 0.1986755 | D22: =$I$4+3*SQRT($I$4/P2_Data!M20) -> 0.74458139 | E22: =MAX(0,$I$4-3*SQRT($I$4/P2_Data!M20)) -> 0 | H22: =P2_Data!A17 -> 11 | I22: =P2_Data!H17 -> 5 | J22: =$I$5 -> 4.0333333 | K22: =MIN(7,$I$5+3*SQRT((1-$I$6)/$I$6^2)) -> 7 | L22: =MAX(0,$I$5-3*SQRT((1-$I$6)/$I$6^2)) -> 0
A23: =P2_Data!A21 -> 15 | B23: =P2_Data!N21 -> 0.2 | C23: =$I$4 -> 0.1986755 | D23: =$I$4+3*SQRT($I$4/P2_Data!M21) -> 0.79668544 | E23: =MAX(0,$I$4-3*SQRT($I$4/P2_Data!M21)) -> 0 | H23: =P2_Data!A18 -> 12 | I23: =P2_Data!H18 -> 3 | J23: =$I$5 -> 4.0333333 | K23: =MIN(7,$I$5+3*SQRT((1-$I$6)/$I$6^2)) -> 7 | L23: =MAX(0,$I$5-3*SQRT((1-$I$6)/$I$6^2)) -> 0
... A38: =P2_Data!A36 -> 30 | B38: =P2_Data!N36 -> 0.2 | C38: =$I$4 -> 0.1986755 | D38: =$I$4+3*SQRT($I$4/P2_Data!M36) -> 0.79668544 | E38: =MAX(0,$I$4-3*SQRT($I$4/P2_Data!M36)) -> 0 | H38: =P2_Data!A33 -> 27 | I38: =P2_Data!H33 -> 3 | J38: =$I$5 -> 4.0333333 | K38: =MIN(7,$I$5+3*SQRT((1-$I$6)/$I$6^2)) -> 7 | L38: =MAX(0,$I$5-3*SQRT((1-$I$6)/$I$6^2)) -> 0
H39: =P2_Data!A34 -> 28 | I39: =P2_Data!H34 -> 3 | J39: =$I$5 -> 4.0333333 | K39: =MIN(7,$I$5+3*SQRT((1-$I$6)/$I$6^2)) -> 7 | L39: =MAX(0,$I$5-3*SQRT((1-$I$6)/$I$6^2)) -> 0
H40: =P2_Data!A35 -> 29 | I40: =P2_Data!H35 -> 3 | J40: =$I$5 -> 4.0333333 | K40: =MIN(7,$I$5+3*SQRT((1-$I$6)/$I$6^2)) -> 7 | L40: =MAX(0,$I$5-3*SQRT((1-$I$6)/$I$6^2)) -> 0
H41: =P2_Data!A36 -> 30 | I41: =P2_Data!H36 -> 4 | J41: =$I$5 -> 4.0333333 | K41: =MIN(7,$I$5+3*SQRT((1-$I$6)/$I$6^2)) -> 7 | L41: =MAX(0,$I$5-3*SQRT((1-$I$6)/$I$6^2)) -> 0
H56: g-chart boundary note
H57: The calculated geometric UCL exceeds the physical maximum of seven pieces. Therefore, the g-chart is interpreted as a relative monitoring chart, while the practical upper boundary is seven pieces, representing a completed defect-free assembly. (UCL is capped at 7 in the table for realism.)
A60: PARETO — Process 2 defects by colour
A61: Colour | B61: Defects | C61: Cum %
A62: Orange | B62: =COUNTIF(P2_Data!$G$7:$G$36,A62) -> 11 | C62: =SUM($B$62:B62)/30 -> 0.36666667 | H62: Western Electric Rule Checks (u-chart)
A63: Red | B63: =COUNTIF(P2_Data!$G$7:$G$36,A63) -> 11 | C63: =SUM($B$62:B63)/30 -> 0.73333333 | H63: Rule | I63: Description | J63: Triggered?
A64: Yellow | B64: =COUNTIF(P2_Data!$G$7:$G$36,A64) -> 4 | C64: =SUM($B$62:B64)/30 -> 0.86666667 | H64: Rule 1 | I64: 1 point beyond 3σ | J64: =IF(SUMPRODUCT((B9:B38>D9:D38)*1)>0,"YES","No") -> No
A65: Dark Blue | B65: =COUNTIF(P2_Data!$G$7:$G$36,A65) -> 4 | C65: =SUM($B$62:B65)/30 -> 1 | H65: Rule 2 | I65: 2 of 3 beyond 2σ | J65: Manual review
A66: White | B66: =COUNTIF(P2_Data!$G$7:$G$36,A66) -> 0 | C66: =SUM($B$62:B66)/30 -> 1 | H66: Rule 4 | I66: 8 consecutive one side | J66: =IF(MAX(FREQUENCY(IF(B9:B38>C9:C38,ROW(B9:B38)),IF(B9:B38<=C9:C38,ROW(B9:B38))))>=8,"YES","No") -> No
A67: Light Blue | B67: =COUNTIF(P2_Data!$G$7:$G$36,A67) -> 0 | C67: =SUM($B$62:B67)/30 -> 1
A68: Green | B68: =COUNTIF(P2_Data!$G$7:$G$36,A68) -> 0 | C68: =SUM($B$62:B68)/30 -> 1
A85: Interpretation: Process 2 averages g≈4 acceptable pieces before a defect forces a discard, so most runs fail before the full seven-piece figurine is completed. The u-chart shows defects-per-opportunity scattered around ū with run-specific limits (limits widen for shorter runs). Pareto shows Orange and Red dominate the discard-causing defects, mirroring Process 1 and pointing to the same supplier/colour assignable cause. A higher g is operationally favourable; a hypothetical full assembly (g=7) would be statistically high but a good outcome, not an alarm.
A95: Assignable Cause Analysis — Process 2
A96: Sample_or_Run | B96: Signal_Observed | C96: Possible_Assignable_Cause | D96: Evidence_From_Data | E96: Retain_or_Exclude | F96: Reason | G96: Recommended_Action
...

Sheet Comparison_DPMO_Cost
A1: Process Comparison — DPMO, Hypothesis Test, Cost & Throughput
A3: 1. DPMO & 2-sigma capability | F3: 3. Cost & Throughput
A4: Metric | B4: Process 1 | C4: Process 2 | D4: Better | F4: Assumptions (P2 time = 30 runs × ~0.307 min; completed assemblies from source = 0)
A5: Total defects | B5: =SUM(P1_Data!K7:K48) -> 76 | C5: =SUM(P2_Data!J7:J36) -> 30 | F5: Piece cost (R) | G5: 2
A6: Total opportunities | B6: =SUM(P1_Data!J7:J48) -> 210 | C6: =SUM(P2_Data!M7:M36) -> 151 | F6: Board cost (R) | G6: 5
A7: Defect rate (p) | B7: =B5/B6 -> 0.36190476 | C7: =C5/C6 -> 0.1986755 | D7: =IF(B7<C7,"P1","P2") -> P2 | F7: Discard cost (R) | G7: 20
A8: DPMO | B8: =B7*1000000 -> 361904.76 | C8: =C7*1000000 -> 198675.5 | D8: =IF(B8<C8,"P1","P2") -> P2 | F8: Selling price (R) | G8: 25
A9: 2-sigma benchmark | B9: 308537 | C9: 308537 | F9: P1 completed assemblies | G9: 0
A10: Meets 2-sigma? (DPMO<bench) | B10: =IF(B8<B9,"YES","NO") -> NO | C10: =IF(C8<C9,"YES","NO") -> YES | F10: P2 completed assemblies | G10: 0
F11: P1 time (min) | G11: 15
A12: Process 1 fails the 2-sigma benchmark (361,905 > 308,537 DPMO); Process 2 passes (198,675 < 308,537). | F12: P2 time (min) | G12: 9.21
A14: 2. Two-proportion z-test (H0: p1=p2 vs H1: p1≠p2)
A15: x1 (P1 defects) | B15: =B5 -> 76 | F15: Cost / output | G15: Process 1 | H15: Process 2
A16: n1 (P1 pieces) | B16: =B6 -> 210 | F16: Pieces consumed | H16: =B6 -> 210 | I16: =C6 -> 151
A17: x2 (P2 defects) | B17: =C5 -> 30 | F17: Material (pieces) cost | H17: =H16*G5 -> 420 | I17: =I16*G5 -> 302
A18: n2 (P2 opp.) | B18: =C6 -> 151 | F18: Discard cost | H18: =0 -> 0 | I18: =SUM(P2_Data!K7:K36)*G7 -> 600
A19: p1 | B19: =B15/B16 -> 0.36190476 | F19: Revenue (completed×price) | H19: =G9*G8 -> 0 | I19: =G10*G8 -> 0
A20: p2 | B20: =B17/B18 -> 0.1986755 | F20: Total cost | H20: =H17+H18 -> 420 | I20: =I17+I18 -> 902
A21: pooled p | B21: =(B15+B17)/(B16+B18) -> 0.29362881 | F21: Profit / (loss) | H21: =H19-H20 -> -420 | I21: =I19-I20 -> -902
A22: SE | B22: =SQRT(B21*(1-B21)*(1/B16+1/B18)) -> 0.04859273 | F22: Throughput (assemblies) | H22: =G9 -> 0 | I22: =G10 -> 0
A23: z | B23: =(B19-B20)/B22 -> 3.3591293 | F23: Defect rate | H23: =B7 -> 0.36190476 | I23: =C7 -> 0.1986755
A24: p-value (two-tailed) | B24: =2*(1-NORMSDIST(ABS(B23))) -> 0.00078188466
A25: Decision (α=0.05) | B25: =IF(B24<0.05,"Reject H0","Fail to reject H0") -> Reject H0
A26: Interpretation: with p1≈0.36 and p2≈0.20, the two-tailed z-test (z≈3.36, p≈0.0008) rejects H0 — the two processes differ significantly in defect proportion, with Process 2 markedly lower. Opportunity for P2 is defined as pieces placed including the defective piece (g+1 per discarded run), giving 151 opportunities over 30 runs.
A40: Chart data
A41: Metric | B41: Process 1 | C41: Process 2
A42: DPMO | B42: =B8 -> 361904.76 | C42: =C8 -> 198675.5
A43: Defect rate | B43: =B7 -> 0.36190476 | C43: =C7 -> 0.1986755
A44: Total cost (R) | B44: =H20 -> 420 | C44: =I20 -> 902

Sheet Dashboard_Report_Tables
A1: Tangra Inc. — SPC Dashboard & Report Tables
A2: Author: Nthabiseng Maoka (30224926)
A4: P1 p̄ (defect rate) | D4: P2 defect rate | G4: P1 DPMO
A5: =Comparison_DPMO_Cost!B7 -> 0.36190476 | D5: =Comparison_DPMO_Cost!C7 -> 0.1986755 | G5: =Comparison_DPMO_Cost!B8 -> 361904.76
A7: P2 DPMO | D7: z-statistic | G7: p-value
A8: =Comparison_DPMO_Cost!C8 -> 198675.5 | D8: =Comparison_DPMO_Cost!B23 -> 3.3591293 | G8: =Comparison_DPMO_Cost!B24 -> 0.00078188466
A11: Final process comparison | F11: Chart selection justification
A12: Criterion | B12: Process 1 | C12: Process 2 | D12: Better | F12: Chart | G12: Process | H12: Justification
A13: Defect rate | B13: =Comparison_DPMO_Cost!B7 -> 0.36190476 | C13: =Comparison_DPMO_Cost!C7 -> 0.1986755 | D13: =IF(B13<C13,"P1","P2") -> P2 | F13: p-chart | G13: P1 | H13: fixed n=5, proportion defective — primary rubric chart
A14: DPMO | B14: =Comparison_DPMO_Cost!B8 -> 361904.76 | C14: =Comparison_DPMO_Cost!C8 -> 198675.5 | D14: =IF(B14<C14,"P1","P2") -> P2 | F14: np-chart | G14: P1 | H14: count defective valid (n constant); confirms p-chart
A15: Meets 2σ? | B15: =Comparison_DPMO_Cost!B10 -> NO | C15: =Comparison_DPMO_Cost!C10 -> YES | D15: — | F15: Pareto | G15: both | H15: rank colours to target assignable causes
A16: Statistically stable? | B16: Round-2 limits show colour-driven OOC | C16: Limits run-specific (u-chart) | D16: — | F16: u-chart | G16: P2 | H16: defects per varying opportunity size
A17: Throughput (completed) | B17: =Comparison_DPMO_Cost!G9 -> 0 | C17: =Comparison_DPMO_Cost!G10 -> 0 | D17: — | F17: g-chart | G17: P2 | H17: pieces before defect; higher = better
A20: Defect vs Defective | F20: Assignable causes (evidence-based)
A21: Term | B21: Meaning | F21: • Supplier/colour concentration — White, Yellow, Red, Orange dominate defects in both processes.
A22: Defect | B22: one nonconforming feature on a piece | F22: • Light Blue & Green show zero defects — possible different supplier/bin or inspection focus change.
A23: Defective piece | B23: a piece that cannot be used | F23: • Process 2 discards whole assemblies on first defect — early defects (low g) drive cost.
A24: Defective assembly | B24: a figurine that cannot ship
A25: Non-defective assembly | B25: complete, all 7 pieces fit
A28: Final recommendation
A29: Final recommendation: Process 2 performs better statistically — lower defect rate (≈20% vs ≈36%) and lower DPMO (≈198,675 vs ≈361,905), and the two-proportion z-test (z≈3.36, p≈0.0008) shows the difference is statistically significant. Process 2 passes the 2-sigma benchmark (308,537 DPMO) while Process 1 fails it. However, Process 2 discards the entire semi-assembly on a single defect, making it costly when high-defect colours appear early. Process 1 is operationally attractive because defectives are removed before assembly, but its current DPMO exceeds the 2-sigma benchmark. Priority: reduce supplier/colour-specific defects (White, Yellow, Red, Orange) before full implementation; on current data prefer Process 2 for capability while fixing incoming material quality. Conclusion rests on stability, DPMO/2-sigma, the z-test, cost and throughput together — not a single chart.
A40: Assignable causes summary
A41: • Supplier/colour concentration: White, Dark Blue, Yellow, Red, Orange dominate defects in BOTH processes (Pareto).
A42: • Light Blue & Green: zero defects in P1 — benchmark colours / different supplier or bin.
A43: • Process 2 early discards driven by high-defect colours (Orange/Red) reached early in the pick order.
A44: • No single-point 3σ outlier in P1 (n=5 caps limits) — cause is between-colour, not a rogue subgroup.
